Workbook
Name CCY: 'Notes & Inputs'!#REF!
Name holidays: 'Notes & Inputs'!$C$43:$C$47
Name prevWBS: 'Project Plan'!$A1048576
Name ROLES: 'Notes & Inputs'!$C$21:$C$40
Name START: 'Notes & Inputs'!$C$18
Name valuevx: 42.314159

Sheet 汇总信息项目列表
A1: 序号 | B1: 项目编号 | C1: 项目名称
A2: 1 | B2: 202510045 | C2: 平利路38弄燃气管道改造
A3: 2 | B3: 202510072 | C3: 四达路58弄1-23号燃气管道改造
A4: 3 | B4: 202510082 | C4: 武威东路1082弄燃气管道改造重新设计
A5: 4 | B5: 202510117 | C5: 新港路（四平路—大连路）燃气管道搬迁工程
A6: 5 | B6: 202510113 | C6: 政立路淞沪路-国和路(自投道路改造工程)
A7: 6 | B7: 202507014 | C7: 四平路国泰路、四平路国定路燃气管道改造工程
A8: 7 | B8: 202510066 | C8: 临平北路5弄、89弄、四平路288弄燃气管道改造
A9: 8 | B9: 202510073 | C9: 四平路（庆阳路-溧阳路）燃气管道改造
A10: 9 | B10: 202510042 | C10: 骏达路北段（曹安公路-童家桥路）燃气配套工程
A11: 10 | B11: 202511035 | C11: 圣安达公寓
A12: 11 | B12: 202510065 | C12: 广纪路65弄燃气管道改造
A13: 12 | B13: 202510064 | C13: 广纪路19号燃气管道改造
... A19: 18 | B19: 20251102901 | C19: 申江路(新金桥路-电台路)信息管道工程项目

Sheet Project List
A1: =COLUMN() -> 1 | B1: =COLUMN() -> 2 | C1: =COLUMN() -> 3 | D1: =COLUMN() -> 4 | E1: =COLUMN() -> 5 | F1: =COLUMN() -> 6 | G1: =COLUMN() -> 7 | H1: =COLUMN() -> 8 | ... AJ1: =COLUMN() -> 36
A2: 项目编号 | B2: 项目名称 | C2: 申报线路类型 | D2: 状态 | E2: 监护等级 | F2: 报审项目类型 | G2: 审批状态 | H2: 申报类型 | I2: 申报时间 | J2: 申报工期 | K2: 建设单位 | L2: 项目地理位置 | M2: 与轨道交通关系 | N2: 申报人姓名 | O2: 申报人电话 | P2: 项目负责人姓名 | Q2: 项目负责人电话 | R2: 是否监测 | S2: 监测单位 | T2: 项目类型 | U2: 是否委托 | V2: 项目概况 | W2: 是否为低风险 | X2: 低风险类型 | Y2: 是否涉及规划 | Z2: 是否涉及在建线路 | AA2: 是否涉及申铁线路 | AB2: 作业内容 | AC2: 线路情况 | AD2: 车站 | AE2: 区间 | AF2: 其他设施 | AG2: 风险点 | AH2: 运营安全保障等级 | AI2: 复核验算 | AJ2: 是否编制大纲
A3: 202510045 | B3: 平利路38弄燃气管道改造 | C3: 地铁线 | D3: 审批中 | E3: 三级 | F3: 低风险类作业 | G3: 审批中 | H3: 许可类 | I3: 45973 | J3: 1.0月 | K3: 上海燃气市北销售有限公司 | L3: 普陀区东临志丹路 | M3: 地铁在建线路20号线平利路站车站 | N3: 曹玉轩 | O3: 17712207991 | P3: 季正阳 | Q3: 13761126768 | T3: 管线 | V3: 本项目沿志丹路埋设DN110-160燃气管道，长度280米，挖深1.5米。管道与地铁20号线“平利路站”垂直，与地铁结构最小水平距离14.3米，管底距离车站顶最小竖向净距10.53米。 | W3: 是 | X3: 5、对应地铁地下隧道——挖深不超过4m且围护与区间隧道水平或竖向净距大于5m的明挖类管线工程。 | Y3: 否 | Z3: 是 | AA3: 否 | AB3: 排管工程 | AC3: 在建 | AE3: 单圆 | AG3: 低风险项目 | AJ3: 否
A4: 202510072 | B4: 四达路58弄1-23号燃气管道改造 | C4: 地铁线 | D4: 审批中 | E4: 三级 | F4: 低风险类作业 | G4: 审批中 | H4: 许可类 | I4: 45973 | J4: 1.0月 | K4: 上海燃气市北销售有限公司 | L4: 虹口区东临四平路北临四达路 | M4: 地铁运营线路10号线邮电新村站至海伦路站区间 | N4: 朋炎琰 | O4: 18019381182 | P4: 徐韵 | Q4: 13917571535 | T4: 管线 | V4: 本项目在四达路以北，四平路以西埋设DN110-300燃气管道，长度220米，挖深1.5米。管道与地铁10号线“海伦路站-邮电新村站”区间隧道平行，与地铁结构最小水平距离0.3米，管底距离隧道顶最小竖向净距9.252米。 | W4: 是 | X4: 5、对应地铁地下隧道——挖深不超过4m且围护与区间隧道水平或竖向净距大于5m的明挖类管线工程。 | Y4: 否 | Z4: 否 | AA4: 否 | AB4: 排管工程 | AC4: 运营 | AE4: 单圆 | AG4: 低风险项目 | AJ4: 否
A5: 202510082 | B5: 武威东路1082弄燃气管道改造重新设计 | C5: 地铁线 | D5: 审批中 | E5: 三级 | F5: 低风险类作业 | G5: 审批中 | H5: 许可类 | I5: 45973 | J5: 1.0月 | K5: 上海燃气市北销售有限公司 | L5: 普陀区东临雪松路西临红棉路南临武威路 | M5: 地铁运营线路11号线武威路站至桃浦新村站区间 | N5: 朋炎琰 | O5: 18019381182 | P5: 王健 | Q5: 13818171068 | T5: 管线 | V5: 本项目在武威路以北，雪松路以西埋设DN110-160燃气管道，长度167米，挖深1.5米，管道与地铁11号线“武威路站-桃浦新村站”区间隧道平行，与地铁结构最小水平距离1.9米；DN110-300燃气管道，长度385米，挖深1.5米，管道与地铁11号线“武威路站-桃浦新村站”区间隧道平行，与地铁结构最小水平距离0.7米，管底距离隧道顶最小竖向净距11.473米。 | W5: 是 | X5: 5、对应地铁地下隧道——挖深不超过4m且围护与区间隧道水平或竖向净距大于5m的明挖类管线工程。 | Y5: 否 | Z5: 否 | AA5: 否 | AB5: 排管工程 | AC5: 运营 | AE5: 单圆 | AG5: 低风险项目 | AJ5: 否
A6: 202510117 | B6: 新港路（四平路—大连路）燃气管道搬迁工程 | C6: 地铁线 | D6: 审批中 | E6: 三级 | F6: 低风险类作业 | G6: 审批中 | H6: 许可类 | I6: 45973 | J6: 1.0月 | K6: 上海燃气市北销售有限公司 | L6: 虹口区西临四平路 | M6: 地铁运营线路10号线四平路站至邮电新村站区间 | N6: 曹玉轩 | O6: 17712207991 | P6: 徐韵 | Q6: 13917571535 | T6: 管线 | V6: 本项目在四平路以南，新港路上埋设DN300燃气管道，长度40米，挖深1.5米。管道与地铁10号线“邮电新村站-四平路站”区间隧道垂直，与地铁结构最小水平距离20.6米，管底距离隧道顶最小竖向净距11.334米。 | W6: 是 | X6: 5、对应地铁地下隧道——挖深不超过4m且围护与区间隧道水平或竖向净距大于5m的明挖类管线工程。 | Y6: 否 | Z6: 否 | AA6: 否 | AB6: 排管工程 | AC6: 运营 | AE6: 双圆 | AG6: 低风险项目 | AJ6: 否
A7: 202510113 | B7: 政立路淞沪路-国和路(自投道路改造工程) | C7: 地铁线 | D7: 审批中 | E7: 三级 | F7: 低风险类作业 | G7: 审批中 | H7: 许可类 | I7: 45973 | J7: 1.0月 | K7: 上海燃气市北销售有限公司 | L7: 杨浦区东临国和路西临淞沪路 | M7: 地铁运营线路10号线江湾体育场站至三门路站区间 | N7: 朋炎琰 | O7: 18019381182 | P7: 徐韵 | Q7: 13917571535 | T7: 管线 | V7: 本项目在淞沪路以西，政立路上埋设DN300-500燃气管道，长度130米，挖深1.7米。管道与地铁10号线“江湾体育场-三门路站”区间隧道垂直，与地铁结构最小水平距离0.8米，管底距离隧道顶最小竖向净距13.469米。 | W7: 是 | X7: 5、对应地铁地下隧道——挖深不超过4m且围护与区间隧道水平或竖向净距大于5m的明挖类管线工程。 | Y7: 否 | Z7: 否 | AA7: 否 | AB7: 排管工程 | AC7: 运营 | AE7: 单圆 | AG7: 低风险项目 | AJ7: 否
A8: 202507014 | B8: 四平路国泰路、四平路国定路燃气管道改造工程 | C8: 地铁线 | D8: 审批中 | E8: 三级 | F8: 低风险类作业 | G8: 审批中 | H8: 许可类 | I8: 45973 | J8: 1.0月 | K8: 上海燃气市北销售有限公司 | L8: 杨浦区南临国定路 | M8: 地铁运营线路10号线国权路站至五角场站区间 | N8: 朋炎琰 | O8: 18019381182 | P8: 徐韵 | Q8: 13917571535 | T8: 管线 | V8: 本项目在国泰路以东，四平路上埋设DN200-300燃气管道，长度155米，挖深1.5米，管道与地铁10号线“同济大学站-国权路站”区间隧道垂直，与地铁结构最小水平距离0.7米，管底距离隧道顶最小竖向净距8.209米；在国定路以北，四平路上埋设DN300燃气管道，长度42米，挖深1.5米，管道与地铁10号线“国权路站-五角场站”区间隧道平行，管底距离隧道顶最小竖向净距11.054米。 | W8: 是 | X8: 5、对应地铁地下隧道——挖深不超过4m且围护与区间隧道水平或竖向净距大于5m的明挖类管线工程。 | Y8: 否 | Z8: 否 | AA8: 否 | AB8: 排管工程 | AC8: 运营 | AE8: 单圆 | AG8: 低风险项目 | AJ8: 否
A9: 202510066 | B9: 临平北路5弄、89弄、四平路288弄燃气管道改造 | C9: 地铁线 | D9: 审批中 | E9: 三级 | F9: 低风险类作业 | G9: 审批中 | H9: 许可类 | I9: 45974 | J9: 1.0月 | K9: 上海燃气市北销售有限公司 | L9: 虹口区西临四平路南临临平北路 | M9: 地铁运营线路10号线四平路站至邮电新村站区间 | N9: 曹玉轩 | O9: 18019381182 | P9: 徐韵 | Q9: 13917571535 | T9: 管线 | V9: 本项目在临平路以北，四平路以东埋设DN110-160燃气管道，长度141米，挖深1.5米，管道与地铁10号线“四平路站-邮电新村站”区间隧道垂直，与地铁结构最小水平距离0.7米，管底距离隧道顶最小竖向净距11.541米。 | W9: 是 | X9: 5、对应地铁地下隧道——挖深不超过4m且围护与区间隧道水平或竖向净距大于5m的明挖类管线工程。 | Y9: 否 | Z9: 否 | AA9: 否 | AB9: 排管工程 | AC9: 运营 | AE9: 单圆 | AG9: 低风险项目 | AJ9: 否
A10: 202510073 | B10: 四平路（庆阳路-溧阳路）燃气管道改造 | C10: 地铁线 | D10: 审批中 | F10: 低风险类作业 | G10: 审批中 | H10: 许可类 | I10: 45974 | K10: 上海燃气市北销售有限公司 | L10: 虹口区东临天水路南临赤峰路 | M10: 地铁运营线路10号线海伦路站至邮电新村站区间 | N10: 朋炎琰 | O10: 18019381182 | P10: 徐韵 | Q10: 13917571535 | T10: 管线 | V10: 本项目在四平路和赤峰路路口埋设DN200和DN315燃气管道，长度分别为34和105米，挖深分别为2和1.5米，管道横穿地铁10号线“四平路站-同济大学站”区间隧道，管底距离隧道顶最小竖向净距为11.485米。在四平路（天水路-溧阳路）上埋设DN500、DN315和DN300燃气管道，长度分别为662、73和18米，挖深分别为1.7、1.5和1.5米，管道横穿地铁10号线“海伦路站-邮电新村站”区间隧道，管底距离隧道顶最小竖向净距为6.814米。 | W10: 是 | X10: 5、对应地铁地下隧道——挖深不超过4m且围护与区间隧道水平或竖向净距大于5m的明挖类管线工程。 | Y10: 待确认 | Z10: 是 | AA10: 否 | AG10: 低风险项目 | AJ10: 否
A11: 202510042 | B11: 骏达路北段（曹安公路-童家桥路）燃气配套工程 | C11: 地铁线 | D11: 审批中 | E11: 三级 | F11: 低风险类作业 | G11: 审批中 | H11: 许可类 | I11: 45974 | J11: 1.0月 | K11: 上海燃气市北销售有限公司 | L11: 嘉定区东临曹安公路 | M11: 地铁运营线路14号线曹安公路站至嘉怡路站区间 | N11: 曹玉轩 | O11: 17712207991 | P11: 冯鏐轶 | Q11: 13301751182 | T11: 管线 | V11: 本项目在曹安公路以西埋设DN200燃气管道，长度28.66米，挖深1.5米，管道与地铁14号线“曹安公路站-嘉怡路”区间隧道垂直，与地铁结构最小水平距离21.3米，管底距离隧道顶最小竖向净距12.862米。 | W11: 是 | X11: 5、对应地铁地下隧道——挖深不超过4m且围护与区间隧道水平或竖向净距大于5m的明挖类管线工程。 | Y11: 否 | Z11: 否 | AA11: 否 | AB11: 排管工程 | AC11: 运营 | AE11: 单圆 | AG11: 低风险项目 | AJ11: 否
A12: 202511035 | B12: 圣安达公寓 | C12: 地铁线 | D12: 审批中 | E12: 三级 | F12: 低风险类作业 | G12: 审批中 | H12: 许可类 | I12: 45975 | J12: 1.0月 | K12: 上海圣安达酒店有限公司 | L12: 普陀区东临真北路西临子洲路南临铜川路北临金鼎路 | M12: 地铁运营线路14号线铜川路站至真光路站区间 | N12: 陆会忠 | O12: 13817483399 | P12: 吴群英 | Q12: 18017895955 | T12: 勘探 | V12: 本项目在铜川路1620号为新建保障性租赁住房，用地面积为7221平方米，总建筑面积为33036.98平方米，地上总建筑面积为25934平方米，地下总建筑面积为7102.98平方米，为地下一层地上15层建筑。 | W12: 是 | X12: 2、距离地铁结构10m以外的勘察工程(不包含水勘)。 | Y12: 否 | Z12: 否 | AA12: 否 | AB12: 其他 | AC12: 运营 | AE12: 双圆 | AF12: 旁通道 | AG12: 低风险项目 | AJ12: 否
A13: 202507054 | B13: 世博水环品质提升工程（一期）D段 | C13: 地铁线 | D13: 审批中 | F13: 低风险类作业 | G13: 审批中 | H13: 许可类 | I13: 45975 | K13: 上海市浦东新区生态环境局基建项目和资产管理事务中心 | L13: 浦东新区东临东明路西临规划云台路南临三林路北临三林塘 | M13: 地铁运营线路11号线三林站至三林东站区间 | N13: 谢江明 | O13: 18321669860 | P13: 陈鹏飞 | Q13: 13524486213 | T13: 绿化 | V13: 项目位于上海浦东新区白莲泾、大寨河、人民江、三林塘港、小黄浦两岸。全长10.3 km，建设范围约54公顷。涉及保护区域位于东明公园范围内，北起三林塘，西至规划云台路，南靠三林路，东抵东明路，实施面积为7975.83m² | W13: 是 | X13: 3、荷载满足加载控制要求且无需标高复测的道路、园林绿化类工程。 | Y13: 待确认 | Z13: 是 | AA13: 否 | AG13: 低风险项目 | AJ13: 否
A14: 202510065 | B14: 广纪路65弄燃气管道改造 | C14: 地铁线 | D14: 审批中 | E14: 三级 | F14: 低风险类作业 | G14: 审批中 | H14: 许可类 | I14: 45979 | J14: 1.0月 | K14: 上海燃气市北销售有限公司 | L14: 虹口区东临广济路北临广灵二路 | M14: 地铁运营线路3号线赤峰路车站 | N14: 曹玉轩 | O14: 17712207991 | P14: 徐韵 | Q14: 13917571535 | T14: 管线 | V14: 本项目在广纪路以西，广灵路以南埋设DN150燃气管道，长度35米，挖深1.5米，管道与地铁3号线“赤峰路站”车站高架平行，与高架墩柱最小水平距离7.6米。 | W14: 是 | X14: 6、对应地铁高架————挖深不超过3m且距离高架承台大于3m，并采用横列板支护的明挖管线工程。 | Y14: 否 | Z14: 否 | AA14: 否 | AB14: 排管工程 | AC14: 运营 | AD14: 地上 | AE14: 高架 | AG14: 低风险项目 | AJ14: 否
A15: 202510064 | B15: 广纪路19号燃气管道改造 | C15: 地铁线 | D15: 审批中 | E15: 三级 | F15: 低风险类作业 | G15: 审批中 | H15: 许可类 | I15: 45979 | J15: 1.0月 | K15: 上海燃气市北销售有限公司 | L15: 虹口区东临广纪路 | M15: 地铁运营线路3号线虹口足球场站至赤峰路站区间 | N15: 曹玉轩 | O15: 17712207991 | P15: 徐韵 | Q15: 13917571535 | T15: 管线 | V15: 本项目在广纪路以西埋设DN100燃气管道，长度10米，挖深1.5米，管道与地铁3号线“虹口足球场-赤峰路站”区间高架垂直，与高架墩柱最小水平距离11.8米。 | W15: 是 | X15: 6、对应地铁高架————挖深不超过3m且距离高架承台大于3m，并采用横列板支护的明挖管线工程。 | Y15: 否 | Z15: 否 | AA15: 否 | AB15: 排管工程 | AC15: 运营 | AE15: 高架 | AG15: 低风险项目 | AJ15: 否
A16: 202510099 | B16: 广纪路171弄、中山北一路665号燃气管道改造 | C16: 地铁线 | D16: 审批中 | E16: 三级 | F16: 低风险类作业 | G16: 审批中 | H16: 许可类 | I16: 45979 | J16: 1.0月 | K16: 上海燃气市北销售有限公司 | L16: 虹口区东临广纪路 | M16: 地铁运营线路3号线大柏树站至赤峰路站区间 | N16: 曹玉轩 | O16: 17712207991 | P16: 徐韵 | Q16: 13917571535 | T16: 管线 | V16: 本项目在广纪路上由北向南依次埋设DN110-150，DN200和DN110燃气管道，长度分别为45，15和8米，挖深均为1.5米，管道均与地铁3号线“赤峰路站-大柏树站”区间高架垂直，与高架墩柱最小水平距离12.7米。 | W16: 是 | X16: 6、对应地铁高架————挖深不超过3m且距离高架承台大于3m，并采用横列板支护的明挖管线工程。 | Y16: 否 | Z16: 待确认 | AA16: 待确认 | AB16: 排管工程 | AC16: 运营 | AE16: 高架 | AG16: 低风险项目 | AJ16: 否
A17: 202511063 | B17: 皋兰山路武威路上水排管项目 | C17: 地铁线 | D17: 审批中 | F17: 低风险类作业 | G17: 审批中 | H17: 许可类 | I17: 45980 | K17: 上海城投水务（集团）有限公司自来水业务受理分公司 | L17: 普陀区东临真南路西临山丹路南临永登路北临常和路 | M17: 地铁运营线路11号线武威路车站或桃浦新村站至武威路站区间 | N17: 赵捷 | O17: 13818690097 | P17: 归陈华 | Q17: 13611802252 | T17: 管线 | V17: 根据晋友改投【2021】65号文件，田上海市晋陀区市政工程建设甲心甲请负贡皋兰山路(武南路-常和路)道路新建，本次配合新建道路同步实施上水管线，同时为周边项目配套接水，拟排皋兰山路(武南路-常和路)DN300上水管线约800米。 | W17: 是 | X17: 5、对应地铁地下隧道——挖深不超过4m且围护与区间隧道水平或竖向净距大于5m的明挖类管线工程。 | Y17: 否 | Z17: 待确认 | AA17: 待确认 | AG17: 低风险项目 | AJ17: 否
A18: 202504072 | B18: 世博水环品质提升工程（一期）D段 | C18: 地铁线 | D18: 审批中 | E18: 三级 | F18: 低风险类作业 | G18: 审批中 | H18: 许可类 | I18: 45981 | J18: 3.0月 | K18: 上海市浦东新区生态环境局基建项目和资产管理事务中心 | L18: 浦东新区东临东明路西临规划云台路南临三林路北临三林塘 | M18: 地铁运营线路11号线三林站至三林东站区间 | N18: 谢江明 | O18: 18321669860 | P18: 陈鹏飞 | Q18: 13524486213 | T18: 绿化 | V18: 项目位于上海浦东新区白莲泾、大寨河、人民江、三林塘港、小黄浦两岸。全长10.3km，建设范围约54公顷。涉及保护区域位于东明公园范围内，北起三林塘，西至规划云台路，南靠三林路，东抵东明路，实施面积为7975.83m2 | W18: 是 | X18: 3、荷载满足加载控制要求且无需标高复测的道路、园林绿化类工程。 | Y18: 否 | Z18: 否 | AA18: 否 | AB18: 加卸载工程 | AC18: 运营 | AE18: 单圆 | AF18: 旁通道 | AG18: 低风险项目 | AJ18: 否
A19: 202511064 | B19: 上海市区长宁愚园路699号项目接入工程 | C19: 地铁线 | D19: 审批中 | E19: 三级 | F19: 低风险类作业 | G19: 审批中 | H19: 许可类 | I19: 45981 | J19: 1.0月 | K19: 国网上海市电力公司市区供电公司 | L19: 长宁区东临镇宁路西临愚园路749弄南临愚园路南侧北临愚园路北侧 | M19: 地铁运营线路2号线静安寺车站或江苏路站至江苏路站区间 | N19: 王哲坤 | O19: 13914387355 | P19: 帅建尧 | Q19: 13310025167 | T19: 管线 | V19: 本工程位于长宁区，本次于道路南侧人行道距规划道路红线0.6米（距规划道路中心线11.4米）处直埋敷设0.4kV电力电缆 1根，并在合适位置利用现状电力排管过路接通上级电源点，长度约为80米。直埋覆土深度0.8米，管底距隧顶垂直距离为12.004米。 | W19: 是 | X19: 5、对应地铁地下隧道——挖深不超过4m且围护与区间隧道水平或竖向净距大于5m的明挖类管线工程。 | Y19: 否 | Z19: 否 | AA19: 否 | AB19: 排管工程 | AC19: 运营 | AE19: 单圆 | AG19: 低风险项目 | AJ19: 否
A20: 202503068 | B20: 浦东新区张杨路城市资源回收中心项目 | C20: 地铁线 | D20: 审批中 | F20: 非 低风险类作业
A21: 202511028 | B21: 申江路(陇桥路-新金桥路)信息管道工程项目 | C21: 地铁线 | D21: 审批中 | F21: 低风险类作业 | G21: 审批中 | H21: 许可类 | I21: 45985 | K21: 上海市信息管线有限公司 | L21: 浦东新区南临陇桥路北临新金桥路 | M21: 地铁运营线路9号线金桥站至金吉路站区间 | N21: 靳婷 | O21: 13761587091 | P21: 马震 | Q21: 13681608289 | T21: 管线 | V21: 涉及地铁9号线、管线位置在申江路西侧人行道与金海路地铁9号线交叉，开挖深度1米、采用挡土板支护。 | W21: 是 | X21: 5、对应地铁地下隧道——挖深不超过4m且围护与区间隧道水平或竖向净距大于5m的明挖类管线工程。 | Y21: 待确认 | Z21: 是 | AA21: 否 | AG21: 低风险项目 | AJ21: 否
A22: 20251102901 | B22: 申江路(新金桥路-电台路)信息管道工程项目 | C22: 地铁线 | D22: 审批中 | F22: 低风险类作业 | G22: 审批中 | H22: 许可类 | I22: 45985 | K22: 上海市信息管线有限公司 | L22: 浦东新区南临新金桥路北临电台路 | M22: 地铁运营线路14号线浦东足球场站站至金粤路站区间 | N22: 靳婷 | O22: 13761587091 | P22: 马震 | Q22: 13681608289 | T22: 管线 | V22: 申江路(电台路-新金桥路)为信息管道开挖工程：涉及地铁14号线、管线位置在申江路西侧人行道与锦绣路地铁14号线交叉，开挖深度1米、采用挡土板支护。 | W22: 是 | X22: 5、对应地铁地下隧道——挖深不超过4m且围护与区间隧道水平或竖向净距大于5m的明挖类管线工程。 | Y22: 待确认 | Z22: 否 | AA22: 否 | AG22: 低风险项目 | AJ22: 否

Sheet Project Plan
N1: =IF($G1=H$1,"t","") -> t | Q1: 交付
N2: =IF($G2=H$1,"t","") -> t | Q2: 会议安排
Q3: 当前日期
Q4: 法定节假日
N6: ="Week "&(N8-(START-WEEKDAY(START,1)+2))/7+1 -> Week 2 | U6: ="Week "&(U8-(START-WEEKDAY(START,1)+2))/7+1 -> Week 3 | AB6: ="Week "&(AB8-(START-WEEKDAY(START,1)+2))/7+1 -> Week 4 | AI6: ="Week "&(AI8-(START-WEEKDAY(START,1)+2))/7+1 -> Week 5 | AP6: ="Week "&(AP8-(START-WEEKDAY(START,1)+2))/7+1 -> Week 6 | AW6: ="Week "&(AW8-(START-WEEKDAY(START,1)+2))/7+1 -> Week 7 | BD6: ="Week "&(BD8-(START-WEEKDAY(START,1)+2))/7+1 -> Week 8 | BK6: ="Week "&(BK8-(START-WEEKDAY(START,1)+2))/7+1 -> Week 9 | BR6: ="Week "&(BR8-(START-WEEKDAY(START,1)+2))/7+1 -> Week 10 | BY6: ="Week "&(BY8-(START-WEEKDAY(START,1)+2))/7+1 -> #REF! | CD6: ="Week "&(CD8-(START-WEEKDAY(START,1)+2))/7+1 -> #REF! | CI6: ="Week "&(CI8-(START-WEEKDAY(START,1)+2))/7+1 -> #REF! | CN6: ="Week "&(CN8-(START-WEEKDAY(START,1)+2))/7+1 -> #REF! | CS6: ="Week "&(CS8-(START-WEEKDAY(START,1)+2))/7+1 -> #REF! | CX6: ="Week "&(CX8-(START-WEEKDAY(START,1)+2))/7+1 -> #REF! | DC6: ="Week "&(DC8-(START-WEEKDAY(START,1)+2))/7+1 -> #REF!
C7: =_xlfn.IFNA(MATCH(C$8,'Project List'!$2:$2,0),-1) -> 2 | D7: =_xlfn.IFNA(MATCH(D$8,'Project List'!$2:$2,0),-1) -> 20 | E7: =_xlfn.IFNA(MATCH(E$8,'Project List'!$2:$2,0),-1) -> 13 | F7: =_xlfn.IFNA(MATCH(F$8,'Project List'!$2:$2,0),-1) -> 9 | L7: 2 | N7: =N8 -> 45964 | U7: =U8 -> 45971 | AB7: =AB8 -> 45978 | AI7: =AI8 -> 45985 | AP7: =AP8 -> 45992 | AW7: =AW8 -> 45999 | BD7: =BD8 -> 46006 | BK7: =BK8 -> 46013 | BR7: =BR8 -> 46020 | BY7: =BY8 -> #REF! | CD7: =CD8 -> #REF! | CI7: =CI8 -> #REF! | CN7: =CN8 -> #REF! | CS7: =CS8 -> #REF! | CX7: =CX8 -> #REF! | DC7: =DC8 -> #REF!
A8: 序号 | B8: 项目编号 | C8: 项目名称 | D8: 项目类型 | E8: 与轨道交通关系 | F8: 申报时间 | G8: 完成 时间 | H8: 进度 | I8: 关键日 | J8: 监护大 纲状态 | K8: 技审状态 | L8: 备注 | N8: =START-WEEKDAY(START,1)+2+7*(L7-1) -> 45964 | O8: =N8+1 -> 45965 | P8: =O8+1 -> 45966 | Q8: =P8+1 -> 45967 | R8: =Q8+1 -> 45968 | S8: =R8+1 -> 45969 | T8: =S8+1 -> 45970 | U8: =T8+1 -> 45971 | V8: =U8+1 -> 45972 | ... BX8: =BW8+1 -> 46026 | BY8: =#REF!+3 -> #REF! | BZ8: =BY8+1 -> #REF! | CA8: =BZ8+1 -> #REF! | CB8: =CA8+1 -> #REF! | CC8: =CB8+1 -> #REF! | CD8: =CC8+3 -> #REF! | CE8: =CD8+1 -> #REF! | CF8: =CE8+1 -> #REF! | CG8: =CF8+1 -> #REF! | CH8: =CG8+1 -> #REF! | CI8: =CH8+3 -> #REF! | CJ8: =CI8+1 -> #REF! | CK8: =CJ8+1 -> #REF! | CL8: =CK8+1 -> #REF! | CM8: =CL8+1 -> #REF! | CN8: =CM8+3 -> #REF! | CO8: =CN8+1 -> #REF! | CP8: =CO8+1 -> #REF! | CQ8: =CP8+1 -> #REF! | CR8: =CQ8+1 -> #REF! | CS8: =CR8+3 -> #REF! | CT8: =CS8+1 -> #REF! | CU8: =CT8+1 -> #REF! | CV8: =CU8+1 -> #REF! | CW8: =CV8+1 -> #REF! | CX8: =CW8+3 -> #REF! | CY8: =CX8+1 -> #REF! | CZ8: =CY8+1 -> #REF! | DA8: =CZ8+1 -> #REF! | DB8: =DA8+1 -> #REF! | DC8: =DB8+3 -> #REF! | DD8: =DC8+1 -> #REF! | DE8: =DD8+1 -> #REF! | DF8: =DE8+1 -> #REF! | DG8: =DF8+1 -> #REF!
A9: 轨道交通信息 | B9: 轨道交通信息 | C9: 轨道交通信息 | D9: 轨道交通信息 | E9: 轨道交通信息 | N9: =CHOOSE(WEEKDAY(N8,1),"SUN","M","T","W","T","F","SAR") -> M | O9: =CHOOSE(WEEKDAY(O8,1),"SUN","M","T","W","T","F","SAR") -> T | P9: =CHOOSE(WEEKDAY(P8,1),"SUN","M","T","W","T","F","SAR") -> W | Q9: =CHOOSE(WEEKDAY(Q8,1),"SUN","M","T","W","T","F","SAR") -> T | R9: =CHOOSE(WEEKDAY(R8,1),"SUN","M","T","W","T","F","SAR") -> F | S9: =CHOOSE(WEEKDAY(S8,1),"SUN","M","T","W","T","F","SAR") -> SAR | T9: =CHOOSE(WEEKDAY(T8,1),"SUN","M","T","W","T","F","SAR") -> SUN | U9: =CHOOSE(WEEKDAY(U8,1),"SUN","M","T","W","T","F","SAR") -> M | ... BX9: =CHOOSE(WEEKDAY(BX8,1),"SUN","M","T","W","T","F","SAR") -> SUN | BY9: =CHOOSE(WEEKDAY(BY8,1),"S","M","T","W","T","F","S") -> #REF! | BZ9: =CHOOSE(WEEKDAY(BZ8,1),"S","M","T","W","T","F","S") -> #REF! | CA9: =CHOOSE(WEEKDAY(CA8,1),"S","M","T","W","T","F","S") -> #REF! | CB9: =CHOOSE(WEEKDAY(CB8,1),"S","M","T","W","T","F","S") -> #REF! | CC9: =CHOOSE(WEEKDAY(CC8,1),"S","M","T","W","T","F","S") -> #REF! | CD9: =CHOOSE(WEEKDAY(CD8,1),"S","M","T","W","T","F","S") -> #REF! | CE9: =CHOOSE(WEEKDAY(CE8,1),"S","M","T","W","T","F","S") -> #REF! | CF9: =CHOOSE(WEEKDAY(CF8,1),"S","M","T","W","T","F","S") -> #REF! | ... DG9: =CHOOSE(WEEKDAY(DG8,1),"S","M","T","W","T","F","S") -> #REF!
A10: =IF(ISERROR(VALUE(SUBSTITUTE(prevWBS,".",""))),"1",IF(ISERROR(FIND("`",SUBSTITUTE(prevWBS,".","`",1))),TEXT(VALUE(prevWBS)+1,"#"),TEXT(VALUE(LEFT(prevWBS,FIND("`",SUBSTITUTE(prevWBS,".","`",1))-1))+1,"#"))) -> 1 | C10: 技术审查【许可类】 | N10: =IF($I10=N$8,"t","") | O10: =IF($I10=O$8,"t","") | P10: =IF($I10=P$8,"t","") | Q10: =IF($I10=Q$8,"t","") | T10: =IF($I10=T$8,"t","") | U10: =IF($I10=U$8,"t","") | V10: =IF($I10=V$8,"t","") | W10: =IF($I10=W$8,"t","") | X10: =IF($I10=X$8,"t","") | AA10: =IF($I10=AA$8,"t","") | AB10: =IF($I10=AB$8,"t","") | AC10: =IF($I10=AC$8,"t","") | AD10: =IF($I10=AD$8,"t","") | AG10: =IF($I10=AG$8,"t","") | AH10: =IF($I10=AH$8,"t","") | AI10: =IF($I10=AI$8,"t","") | AJ10: =IF($I10=AJ$8,"t","") | AK10: =IF($I10=AK$8,"t","") | AN10: =IF($I10=AN$8,"t","") | AO10: =IF($I10=AO$8,"t","") | AP10: =IF($I10=AP$8,"t","") | AQ10: =IF($I10=AQ$8,"t","") | AT10: =IF($I10=AT$8,"t","") | AU10: =IF($I10=AU$8,"t","") | AV10: =IF($I10=AV$8,"t","") | AW10: =IF($I10=AW$8,"t","") | AX10: =IF($I10=AX$8,"t","") | AY10: =IF($I10=AY$8,"t","") | BB10: =IF($I10=BB$8,"t","") | BC10: =IF($I10=BC$8,"t","") | BD10: =IF($I10=BD$8,"t","") | BE10: =IF($I10=BE$8,"t","") | BF10: =IF($I10=BF$8,"t","") | BI10: =IF($I10=BI$8,"t","") | BJ10: =IF($I10=BJ$8,"t","") | BK10: =IF($I10=BK$8,"t","") | BL10: =IF($I10=BL$8,"t","") | BM10: =IF($I10=BM$8,"t","") | BN10: =IF($I10=BN$8,"t","") | BQ10: =IF($I10=BQ$8,"t","") | BR10: =IF($I10=BR$8,"t","") | BS10: =IF($I10=BS$8,"t","") | BT10: =IF($I10=BT$8,"t","") | BW10: =IF($I10=BW$8,"t","") | BX10: =IF($I10=BX$8,"t","") | BY10: =IF($I10=BY$8,"t","") -> #REF! | BZ10: =IF($I10=BZ$8,"t","") -> #REF! | CA10: =IF($I10=CA$8,"t","") -> #REF! | CB10: =IF($I10=CB$8,"t","") -> #REF! | CC10: =IF($I10=CC$8,"t","") -> #REF! | CD10: =IF($I10=CD$8,"t","") -> #REF! | ... DG10: =IF($I10=DG$8,"t","") -> #REF!
A11: =IF(ISERROR(VALUE(SUBSTITUTE(prevWBS,".",""))),"0.1",IF(ISERROR(FIND("`",SUBSTITUTE(prevWBS,".","`",1))),prevWBS&".1",LEFT(prevWBS,FIND("`",SUBSTITUTE(prevWBS,".","`",1)))&IF(ISERROR(FIND("`",SUBSTITUTE(prevWBS,".","`",2))),VALUE(RIGHT(prevWBS,LEN(prevWBS)-FIND("`",SUBSTITUTE(prevWBS,".","`",1))))+1,VALUE(MID(prevWBS,FIND("`",SUBSTITUTE(prevWBS,".","`",1))+1,(FIND("`",SUBSTITUTE(prevWBS,".","`",2))-FIND("`",SUBSTITUTE(prevWBS,".","`",1))-1)))+1))) -> 1.1 | B11: 202510016 | C11: 长阳路2555号内燃气调压器搬迁地铁 | E11: 12号线隆昌路车站 | F11: 45968 | G11: =F11+7 -> 45975 | H11: =IF(OR(K11="销项",K11="已上传",K11="退回"),1,IF(K11="待上传",0.7,IF(K11="已发校审未返",0.3,IF(OR(K11="需沟通",K11="退回"),0,-1)))) -> 1 | I11: - | J11: 已通过 | K11: 退回 | L11: 管道上穿地铁12号线“隆昌路站”，具有打穿风险，不属于低风险类。原则上管底距离车站结构（注意上翻梁）顶标高不小于0.5m。 | M11: =IF($I11=N$8,"t","") | O11: =IF($I11=O$8,"t","") | P11: =IF($I11=P$8,"t","") | Q11: =IF($I11=Q$8,"t","") | R11: =IF($I11=R$8,"t","") | S11: =IF($I11=S$8,"t","") | T11: =IF($I11=T$8,"t","") | U11: =IF($I11=U$8,"t","") | V11: =IF($I11=V$8,"t","") | ... DG11: =IF($I11=DG$8,"t","") -> #REF!
A12: =IF(ISERROR(VALUE(SUBSTITUTE(prevWBS,".",""))),"0.1",IF(ISERROR(FIND("`",SUBSTITUTE(prevWBS,".","`",1))),prevWBS&".1",LEFT(prevWBS,FIND("`",SUBSTITUTE(prevWBS,".","`",1)))&IF(ISERROR(FIND("`",SUBSTITUTE(prevWBS,".","`",2))),VALUE(RIGHT(prevWBS,LEN(prevWBS)-FIND("`",SUBSTITUTE(prevWBS,".","`",1))))+1,VALUE(MID(prevWBS,FIND("`",SUBSTITUTE(prevWBS,".","`",1))+1,(FIND("`",SUBSTITUTE(prevWBS,".","`",2))-FIND("`",SUBSTITUTE(prevWBS,".","`",1))-1)))+1))) -> 1.2 | B12: 202510031 | C12: 大渡河路1262弄燃气管道改造 | E12: 15号线“梅岭北路站～大渡河路站”区间 | F12: 45968 | G12: =F12+7 -> 45975 | H12: =IF(OR(K12="销项",K12="已上传",K12="退回"),1,IF(K12="待上传",0.7,IF(K12="已发校审未返",0.3,IF(OR(K12="需沟通",K12="退回"),0,-1)))) -> 1 | I12: - | J12: 已通过 | K12: 已上传 | N12: =IF($I12=N$8,"t","") | O12: =IF($I12=O$8,"t","") | P12: =IF($I12=P$8,"t","") | Q12: =IF($I12=Q$8,"t","") | R12: =IF($I12=R$8,"t","") | S12: =IF($I12=S$8,"t","") | T12: =IF($I12=T$8,"t","") | U12: =IF($I12=U$8,"t","") | ... DG12: =IF($I12=DG$8,"t","") -> #REF!
A13: =IF(ISERROR(VALUE(SUBSTITUTE(prevWBS,".",""))),"0.1",IF(ISERROR(FIND("`",SUBSTITUTE(prevWBS,".","`",1))),prevWBS&".1",LEFT(prevWBS,FIND("`",SUBSTITUTE(prevWBS,".","`",1)))&IF(ISERROR(FIND("`",SUBSTITUTE(prevWBS,".","`",2))),VALUE(RIGHT(prevWBS,LEN(prevWBS)-FIND("`",SUBSTITUTE(prevWBS,".","`",1))))+1,VALUE(MID(prevWBS,FIND("`",SUBSTITUTE(prevWBS,".","`",1))+1,(FIND("`",SUBSTITUTE(prevWBS,".","`",2))-FIND("`",SUBSTITUTE(prevWBS,".","`",1))-1)))+1))) -> 1.3 | B13: 202510101 | C13: 广中西路883弄燃气管道改造工程 | E13: 20号线大宁公园站站至平利路站站区间 | F13: 45968 | G13: =F13+7 -> 45975 | H13: =IF(OR(K13="销项",K13="已上传",K13="退回"),1,IF(K13="待上传",0.7,IF(K13="已发校审未返",0.3,IF(OR(K13="需沟通",K13="退回"),0,-1)))) -> 1 | I13: - | J13: 销项 | K13: 销项 | L13: 目前距离大宁公园站土体结构52m，请复核一下是否在大宁公园站北侧出入口的保护区范围内，如果不在，那就不用报了，销项就行。 | N13: =IF($I13=N$8,"t","") | O13: =IF($I13=O$8,"t","") | P13: =IF($I13=P$8,"t","") | Q13: =IF($I13=Q$8,"t","") | R13: =IF($I13=R$8,"t","") | S13: =IF($I13=S$8,"t","") | T13: =IF($I13=T$8,"t","") | U13: =IF($I13=U$8,"t","") | ... DG13: =IF($I13=DG$8,"t","") -> #REF!
A14: =IF(ISERROR(VALUE(SUBSTITUTE(prevWBS,".",""))),"0.1",IF(ISERROR(FIND("`",SUBSTITUTE(prevWBS,".","`",1))),prevWBS&".1",LEFT(prevWBS,FIND("`",SUBSTITUTE(prevWBS,".","`",1)))&IF(ISERROR(FIND("`",SUBSTITUTE(prevWBS,".","`",2))),VALUE(RIGHT(prevWBS,LEN(prevWBS)-FIND("`",SUBSTITUTE(prevWBS,".","`",1))))+1,VALUE(MID(prevWBS,FIND("`",SUBSTITUTE(prevWBS,".","`",1))+1,(FIND("`",SUBSTITUTE(prevWBS,".","`",2))-FIND("`",SUBSTITUTE(prevWBS,".","`",1))-1)))+1))) -> 1.4 | B14: 202510163 | C14: 桃浦西路(古浪路-真北路)燃气管道改造 | E14: 15号线武威东路站车站或武威东路站站至古浪路站站区间 | F14: 45968 | G14: =F14+7 -> 45975 | H14: =IF(OR(K14="销项",K14="已上传",K14="退回"),1,IF(K14="待上传",0.7,IF(K14="已发校审未返",0.3,IF(OR(K14="需沟通",K14="退回"),0,-1)))) -> 1 | I14: - | J14: 退回 | K14: 退回 | L14: 桃浦西路(古浪路-真北路)燃气管道改造距离武威东路站地铁车站2B出入口天桥桥墩距离为1.2m，不属于低风险类项目。 | N14: =IF($I14=N$8,"t","") | O14: =IF($I14=O$8,"t","") | P14: =IF($I14=P$8,"t","") | Q14: =IF($I14=Q$8,"t","") | R14: =IF($I14=R$8,"t","") | S14: =IF($I14=S$8,"t","") | T14: =IF($I14=T$8,"t","") | U14: =IF($I14=U$8,"t","") | ... DG14: =IF($I14=DG$8,"t","") -> #REF!
A15: =IF(ISERROR(VALUE(SUBSTITUTE(prevWBS,".",""))),"0.1",IF(ISERROR(FIND("`",SUBSTITUTE(prevWBS,".","`",1))),prevWBS&".1",LEFT(prevWBS,FIND("`",SUBSTITUTE(prevWBS,".","`",1)))&IF(ISERROR(FIND("`",SUBSTITUTE(prevWBS,".","`",2))),VALUE(RIGHT(prevWBS,LEN(prevWBS)-FIND("`",SUBSTITUTE(prevWBS,".","`",1))))+1,VALUE(MID(prevWBS,FIND("`",SUBSTITUTE(prevWBS,".","`",1))+1,(FIND("`",SUBSTITUTE(prevWBS,".","`",2))-FIND("`",SUBSTITUTE(prevWBS,".","`",1))-1)))+1))) -> 1.5 | B15: 20240200501 | C15: 浦东新区周家渡社区Z000203单元13-08地块（勘察） | E15: 13号线“东明路车站～华鹏路站”区间（含东明路车站）、6号线“东明路车站～高科西路站”区间（含东明路车站） | F15: 45968 | G15: =F15+7 -> 45975 | H15: =IF(OR(K15="销项",K15="已上传",K15="退回"),1,IF(K15="待上传",0.7,IF(K15="已发校审未返",0.3,IF(OR(K15="需沟通",K15="退回"),0,-1)))) -> 1 | I15: - | J15: 已通过 | K15: 已上传 | N15: =IF($I15=N$8,"t","") | O15: =IF($I15=O$8,"t","") | P15: =IF($I15=P$8,"t","") | Q15: =IF($I15=Q$8,"t","") | R15: =IF($I15=R$8,"t","") | S15: =IF($I15=S$8,"t","") | T15: =IF($I15=T$8,"t","") | U15: =IF($I15=U$8,"t","") | ... DG15: =IF($I15=DG$8,"t","") -> #REF!
A16: =IF(ISERROR(VALUE(SUBSTITUTE(prevWBS,".",""))),"0.1",IF(ISERROR(FIND("`",SUBSTITUTE(prevWBS,".","`",1))),prevWBS&".1",LEFT(prevWBS,FIND("`",SUBSTITUTE(prevWBS,".","`",1)))&IF(ISERROR(FIND("`",SUBSTITUTE(prevWBS,".","`",2))),VALUE(RIGHT(prevWBS,LEN(prevWBS)-FIND("`",SUBSTITUTE(prevWBS,".","`",1))))+1,VALUE(MID(prevWBS,FIND("`",SUBSTITUTE(prevWBS,".","`",1))+1,(FIND("`",SUBSTITUTE(prevWBS,".","`",2))-FIND("`",SUBSTITUTE(prevWBS,".","`",1))-1)))+1))) -> 1.6 | B16: 202510060 | C16: 共和新路4618弄燃气管道改造 | E16: 1号线“共康路站-彭浦新村站”区间 | F16: 45971 | G16: =F16+7 -> 45978 | H16: =IF(OR(K16="销项",K16="已上传",K16="退回"),1,IF(K16="待上传",0.7,IF(K16="已发校审未返",0.3,IF(OR(K16="需沟通",K16="退回"),0,-1)))) -> 1 | I16: - | J16: 已通过 | K16: 已上传 | N16: =IF($I16=N$8,"t","") | O16: =IF($I16=O$8,"t","") | P16: =IF($I16=P$8,"t","") | Q16: =IF($I16=Q$8,"t","") | R16: =IF($I16=R$8,"t","") | S16: =IF($I16=S$8,"t","") | T16: =IF($I16=T$8,"t","") | U16: =IF($I16=U$8,"t","") | ... DG16: =IF($I16=DG$8,"t","") -> #REF!
A17: =IF(ISERROR(VALUE(SUBSTITUTE(prevWBS,".",""))),"0.1",IF(ISERROR(FIND("`",SUBSTITUTE(prevWBS,".","`",1))),prevWBS&".1",LEFT(prevWBS,FIND("`",SUBSTITUTE(prevWBS,".","`",1)))&IF(ISERROR(FIND("`",SUBSTITUTE(prevWBS,".","`",2))),VALUE(RIGHT(prevWBS,LEN(prevWBS)-FIND("`",SUBSTITUTE(prevWBS,".","`",1))))+1,VALUE(MID(prevWBS,FIND("`",SUBSTITUTE(prevWBS,".","`",1))+1,(FIND("`",SUBSTITUTE(prevWBS,".","`",2))-FIND("`",SUBSTITUTE(prevWBS,".","`",1))-1)))+1))) -> 1.7 | B17: 202510079 | C17: 花园路(水电路-西江湾路)燃气管道改造 | E17: 8号线“虹口足球场站-西藏北路站”区间（含虹口足球场站） | F17: 45971 | G17: =F17+7 -> 45978 | H17: =IF(OR(K17="销项",K17="已上传",K17="退回"),1,IF(K17="待上传",0.7,IF(K17="已发校审未返",0.3,IF(OR(K17="需沟通",K17="退回"),0,-1)))) -> 1 | I17: - | J17: 已通过 | K17: 已上传 | N17: =IF($I17=N$8,"t","") | O17: =IF($I17=O$8,"t","") | P17: =IF($I17=P$8,"t","") | Q17: =IF($I17=Q$8,"t","") | R17: =IF($I17=R$8,"t","") | S17: =IF($I17=S$8,"t","") | T17: =IF($I17=T$8,"t","") | U17: =IF($I17=U$8,"t","") | ... DG17: =IF($I17=DG$8,"t","") -> #REF!
A18: =IF(ISERROR(VALUE(SUBSTITUTE(prevWBS,".",""))),"0.1",IF(ISERROR(FIND("`",SUBSTITUTE(prevWBS,".","`",1))),prevWBS&".1",LEFT(prevWBS,FIND("`",SUBSTITUTE(prevWBS,".","`",1)))&IF(ISERROR(FIND("`",SUBSTITUTE(prevWBS,".","`",2))),VALUE(RIGHT(prevWBS,LEN(prevWBS)-FIND("`",SUBSTITUTE(prevWBS,".","`",1))))+1,VALUE(MID(prevWBS,FIND("`",SUBSTITUTE(prevWBS,".","`",1))+1,(FIND("`",SUBSTITUTE(prevWBS,".","`",2))-FIND("`",SUBSTITUTE(prevWBS,".","`",1))-1)))+1))) -> 1.8 | B18: 202501010 | C18: 上海交通大学徐汇校区高金大楼项目-征询 | E18: 用地红线与区间隧道结构外边线最小水平净距约23.49m，T1裙房与区间隧道结构外边线最小净距约44.3m，T1主楼及T2均位于安全保护区以外。地下室结构外边线与区间隧道结构外边线最小净距约58.4m。 | F18: 45972 | G18: =F18+7 -> 45979 | H18: =IF(OR(K18="销项",K18="已上传",K18="退回"),1,IF(K18="待上传",0.7,IF(K18="已发校审未返",0.3,IF(OR(K18="需沟通",K18="退回"),0,-1)))) -> 1 | J18: 已通过 | K18: 已上传
A19: =IF(ISERROR(VALUE(SUBSTITUTE(prevWBS,".",""))),"0.1",IF(ISERROR(FIND("`",SUBSTITUTE(prevWBS,".","`",1))),prevWBS&".1",LEFT(prevWBS,FIND("`",SUBSTITUTE(prevWBS,".","`",1)))&IF(ISERROR(FIND("`",SUBSTITUTE(prevWBS,".","`",2))),VALUE(RIGHT(prevWBS,LEN(prevWBS)-FIND("`",SUBSTITUTE(prevWBS,".","`",1))))+1,VALUE(MID(prevWBS,FIND("`",SUBSTITUTE(prevWBS,".","`",1))+1,(FIND("`",SUBSTITUTE(prevWBS,".","`",2))-FIND("`",SUBSTITUTE(prevWBS,".","`",1))-1)))+1))) -> 1.9 | B19: 202510074 | C19: 四平路850弄燃气管道改造 | F19: - | G19: - | H19: =IF(OR(K19="销项",K19="已上传",K19="退回"),1,IF(K19="待上传",0.7,IF(K19="已发校审未返",0.3,IF(OR(K19="需沟通",K19="退回"),0,-1)))) -> 1 | J19: 退回 | K19: 退回 | L19: 退回修改隧道断面
A20: =IF(ISERROR(VALUE(SUBSTITUTE(prevWBS,".",""))),"0.1",IF(ISERROR(FIND("`",SUBSTITUTE(prevWBS,".","`",1))),prevWBS&".1",LEFT(prevWBS,FIND("`",SUBSTITUTE(prevWBS,".","`",1)))&IF(ISERROR(FIND("`",SUBSTITUTE(prevWBS,".","`",2))),VALUE(RIGHT(prevWBS,LEN(prevWBS)-FIND("`",SUBSTITUTE(prevWBS,".","`",1))))+1,VALUE(MID(prevWBS,FIND("`",SUBSTITUTE(prevWBS,".","`",1))+1,(FIND("`",SUBSTITUTE(prevWBS,".","`",2))-FIND("`",SUBSTITUTE(prevWBS,".","`",1))-1)))+1))) -> 1.10 | B20: 202510084 | C20: 曲阳路58、118弄燃气管道改造 | F20: - | G20: - | H20: =IF(OR(K20="销项",K20="已上传",K20="退回"),1,IF(K20="待上传",0.7,IF(K20="已发校审未返",0.3,IF(OR(K20="需沟通",K20="退回"),0,-1)))) -> 1 | J20: 退回 | K20: 退回 | L20: 退回按非低风险报
A21: =IF(ISERROR(VALUE(SUBSTITUTE(prevWBS,".",""))),"0.1",IF(ISERROR(FIND("`",SUBSTITUTE(prevWBS,".","`",1))),prevWBS&".1",LEFT(prevWBS,FIND("`",SUBSTITUTE(prevWBS,".","`",1)))&IF(ISERROR(FIND("`",SUBSTITUTE(prevWBS,".","`",2))),VALUE(RIGHT(prevWBS,LEN(prevWBS)-FIND("`",SUBSTITUTE(prevWBS,".","`",1))))+1,VALUE(MID(prevWBS,FIND("`",SUBSTITUTE(prevWBS,".","`",1))+1,(FIND("`",SUBSTITUTE(prevWBS,".","`",2))-FIND("`",SUBSTITUTE(prevWBS,".","`",1))-1)))+1))) -> 1.11 | F21: - | G21: - | H21: =IF(OR(K21="销项",K21="已上传",K21="退回"),1,IF(K21="待上传",0.7,IF(K21="已发校审未返",0.3,IF(OR(K21="需沟通",K21="退回"),0,-1)))) -> -1
A22: =IF(ISERROR(VALUE(SUBSTITUTE(prevWBS,".",""))),"0.1",IF(ISERROR(FIND("`",SUBSTITUTE(prevWBS,".","`",1))),prevWBS&".1",LEFT(prevWBS,FIND("`",SUBSTITUTE(prevWBS,".","`",1)))&IF(ISERROR(FIND("`",SUBSTITUTE(prevWBS,".","`",2))),VALUE(RIGHT(prevWBS,LEN(prevWBS)-FIND("`",SUBSTITUTE(prevWBS,".","`",1))))+1,VALUE(MID(prevWBS,FIND("`",SUBSTITUTE(prevWBS,".","`",1))+1,(FIND("`",SUBSTITUTE(prevWBS,".","`",2))-FIND("`",SUBSTITUTE(prevWBS,".","`",1))-1)))+1))) -> 1.12 | B22: 202510045 | C22: =IF(C$7=-1,"",INDEX(INDEX('Project List'!$1:$1048576,0,C$7),MATCH($B22,'Project List'!$A:$A,0))) -> 平利路38弄燃气管道改造 | D22: =IF(D$7=-1,"",INDEX(INDEX('Project List'!$1:$1048576,0,D$7),MATCH($B22,'Project List'!$A:$A,0))) -> 管线 | E22: =IF(E$7=-1,"",INDEX(INDEX('Project List'!$1:$1048576,0,E$7),MATCH($B22,'Project List'!$A:$A,0))) -> 地铁在建线路20号线平利路站车站 | F22: =IF(F$7=-1,"",INDEX(INDEX('Project List'!$1:$1048576,0,F$7),MATCH($B22,'Project List'!$A:$A,0))) -> 45973 | G22: =F22+7 -> 45980 | H22: =IF(OR(K22="销项",K22="已上传",K22="退回"),1,IF(K22="待上传",0.7,IF(K22="已发校审未返",0.3,IF(OR(K22="需沟通",K22="退回"),0,-1)))) -> 1 | I22: - | J22: 已通过 | K22: 已上传 | L22: 等待在建线路意见
A23: =IF(ISERROR(VALUE(SUBSTITUTE(prevWBS,".",""))),"0.1",IF(ISERROR(FIND("`",SUBSTITUTE(prevWBS,".","`",1))),prevWBS&".1",LEFT(prevWBS,FIND("`",SUBSTITUTE(prevWBS,".","`",1)))&IF(ISERROR(FIND("`",SUBSTITUTE(prevWBS,".","`",2))),VALUE(RIGHT(prevWBS,LEN(prevWBS)-FIND("`",SUBSTITUTE(prevWBS,".","`",1))))+1,VALUE(MID(prevWBS,FIND("`",SUBSTITUTE(prevWBS,".","`",1))+1,(FIND("`",SUBSTITUTE(prevWBS,".","`",2))-FIND("`",SUBSTITUTE(prevWBS,".","`",1))-1)))+1))) -> 1.13 | B23: 202510072 | C23: =IF(C$7=-1,"",INDEX(INDEX('Project List'!$1:$1048576,0,C$7),MATCH($B23,'Project List'!$A:$A,0))) -> 四达路58弄1-23号燃气管道改造 | D23: =IF(D$7=-1,"",INDEX(INDEX('Project List'!$1:$1048576,0,D$7),MATCH($B23,'Project List'!$A:$A,0))) -> 管线 | E23: =IF(E$7=-1,"",INDEX(INDEX('Project List'!$1:$1048576,0,E$7),MATCH($B23,'Project List'!$A:$A,0))) -> 地铁运营线路10号线邮电新村站至海伦路站区间 | F23: =IF(F$7=-1,"",INDEX(INDEX('Project List'!$1:$1048576,0,F$7),MATCH($B23,'Project List'!$A:$A,0))) -> 45973 | G23: =F23+7 -> 45980 | H23: =IF(OR(K23="销项",K23="已上传",K23="退回"),1,IF(K23="待上传",0.7,IF(K23="已发校审未返",0.3,IF(OR(K23="需沟通",K23="退回"),0,-1)))) -> 1 | I23: - | J23: 已通过 | K23: 已上传 | N23: =IF($I23=N$8,"t","") | O23: =IF($I23=O$8,"t","") | P23: =IF($I23=P$8,"t","") | Q23: =IF($I23=Q$8,"t","") | R23: =IF($I23=R$8,"t","") | S23: =IF($I23=S$8,"t","") | T23: =IF($I23=T$8,"t","") | U23: =IF($I23=U$8,"t","") | ... DG23: =IF($I23=DG$8,"t","") -> #REF!
A24: =IF(ISERROR(VALUE(SUBSTITUTE(prevWBS,".",""))),"0.1",IF(ISERROR(FIND("`",SUBSTITUTE(prevWBS,".","`",1))),prevWBS&".1",LEFT(prevWBS,FIND("`",SUBSTITUTE(prevWBS,".","`",1)))&IF(ISERROR(FIND("`",SUBSTITUTE(prevWBS,".","`",2))),VALUE(RIGHT(prevWBS,LEN(prevWBS)-FIND("`",SUBSTITUTE(prevWBS,".","`",1))))+1,VALUE(MID(prevWBS,FIND("`",SUBSTITUTE(prevWBS,".","`",1))+1,(FIND("`",SUBSTITUTE(prevWBS,".","`",2))-FIND("`",SUBSTITUTE(prevWBS,".","`",1))-1)))+1))) -> 1.14 | B24: 202510082 | C24: =IF(C$7=-1,"",INDEX(INDEX('Project List'!$1:$1048576,0,C$7),MATCH($B24,'Project List'!$A:$A,0))) -> 武威东路1082弄燃气管道改造重新设计 | D24: =IF(D$7=-1,"",INDEX(INDEX('Project List'!$1:$1048576,0,D$7),MATCH($B24,'Project List'!$A:$A,0))) -> 管线 | E24: =IF(E$7=-1,"",INDEX(INDEX('Project List'!$1:$1048576,0,E$7),MATCH($B24,'Project List'!$A:$A,0))) -> 地铁运营线路11号线武威路站至桃浦新村站区间 | F24: =IF(F$7=-1,"",INDEX(INDEX('Project List'!$1:$1048576,0,F$7),MATCH($B24,'Project List'!$A:$A,0))) -> 45973 | G24: =F24+7 -> 45980 | H24: =IF(OR(K24="销项",K24="已上传",K24="退回"),1,IF(K24="待上传",0.7,IF(K24="已发校审未返",0.3,IF(OR(K24="需沟通",K24="退回"),0,-1)))) -> 1 | I24: - | J24: 已通过 | K24: 已上传 | N24: =IF($I24=N$8,"t","") | O24: =IF($I24=O$8,"t","") | P24: =IF($I24=P$8,"t","") | Q24: =IF($I24=Q$8,"t","") | R24: =IF($I24=R$8,"t","") | S24: =IF($I24=S$8,"t","") | T24: =IF($I24=T$8,"t","") | U24: =IF($I24=U$8,"t","") | ... DG24: =IF($I24=DG$8,"t","") -> #REF!
A25: =IF(ISERROR(VALUE(SUBSTITUTE(prevWBS,".",""))),"0.1",IF(ISERROR(FIND("`",SUBSTITUTE(prevWBS,".","`",1))),prevWBS&".1",LEFT(prevWBS,FIND("`",SUBSTITUTE(prevWBS,".","`",1)))&IF(ISERROR(FIND("`",SUBSTITUTE(prevWBS,".","`",2))),VALUE(RIGHT(prevWBS,LEN(prevWBS)-FIND("`",SUBSTITUTE(prevWBS,".","`",1))))+1,VALUE(MID(prevWBS,FIND("`",SUBSTITUTE(prevWBS,".","`",1))+1,(FIND("`",SUBSTITUTE(prevWBS,".","`",2))-FIND("`",SUBSTITUTE(prevWBS,".","`",1))-1)))+1))) -> 1.15 | B25: 202510117 | C25: =IF(C$7=-1,"",INDEX(INDEX('Project List'!$1:$1048576,0,C$7),MATCH($B25,'Project List'!$A:$A,0))) -> 新港路（四平路—大连路）燃气管道搬迁工程 | D25: =IF(D$7=-1,"",INDEX(INDEX('Project List'!$1:$1048576,0,D$7),MATCH($B25,'Project List'!$A:$A,0))) -> 管线 | E25: =IF(E$7=-1,"",INDEX(INDEX('Project List'!$1:$1048576,0,E$7),MATCH($B25,'Project List'!$A:$A,0))) -> 地铁运营线路10号线四平路站至邮电新村站区间 | F25: =IF(F$7=-1,"",INDEX(INDEX('Project List'!$1:$1048576,0,F$7),MATCH($B25,'Project List'!$A:$A,0))) -> 45973 | G25: =F25+7 -> 45980 | H25: =IF(OR(K25="销项",K25="已上传",K25="退回"),1,IF(K25="待上传",0.7,IF(K25="已发校审未返",0.3,IF(OR(K25="需沟通",K25="退回"),0,-1)))) -> 1 | I25: - | J25: 已通过 | K25: 已上传 | N25: =IF($I25=N$8,"t","") | O25: =IF($I25=O$8,"t","") | P25: =IF($I25=P$8,"t","") | Q25: =IF($I25=Q$8,"t","") | R25: =IF($I25=R$8,"t","") | S25: =IF($I25=S$8,"t","") | T25: =IF($I25=T$8,"t","") | U25: =IF($I25=U$8,"t","") | ... DG25: =IF($I25=DG$8,"t","") -> #REF!
A26: =IF(ISERROR(VALUE(SUBSTITUTE(prevWBS,".",""))),"0.1",IF(ISERROR(FIND("`",SUBSTITUTE(prevWBS,".","`",1))),prevWBS&".1",LEFT(prevWBS,FIND("`",SUBSTITUTE(prevWBS,".","`",1)))&IF(ISERROR(FIND("`",SUBSTITUTE(prevWBS,".","`",2))),VALUE(RIGHT(prevWBS,LEN(prevWBS)-FIND("`",SUBSTITUTE(prevWBS,".","`",1))))+1,VALUE(MID(prevWBS,FIND("`",SUBSTITUTE(prevWBS,".","`",1))+1,(FIND("`",SUBSTITUTE(prevWBS,".","`",2))-FIND("`",SUBSTITUTE(prevWBS,".","`",1))-1)))+1))) -> 1.16 | B26: 202510113 | C26: =IF(C$7=-1,"",INDEX(INDEX('Project List'!$1:$1048576,0,C$7),MATCH($B26,'Project List'!$A:$A,0))) -> 政立路淞沪路-国和路(自投道路改造工程) | D26: =IF(D$7=-1,"",INDEX(INDEX('Project List'!$1:$1048576,0,D$7),MATCH($B26,'Project List'!$A:$A,0))) -> 管线 | E26: =IF(E$7=-1,"",INDEX(INDEX('Project List'!$1:$1048576,0,E$7),MATCH($B26,'Project List'!$A:$A,0))) -> 地铁运营线路10号线江湾体育场站至三门路站区间 | F26: =IF(F$7=-1,"",INDEX(INDEX('Project List'!$1:$1048576,0,F$7),MATCH($B26,'Project List'!$A:$A,0))) -> 45973 | G26: =F26+7 -> 45980 | H26: =IF(OR(K26="销项",K26="已上传",K26="退回"),1,IF(K26="待上传",0.7,IF(K26="已发校审未返",0.3,IF(OR(K26="需沟通",K26="退回"),0,-1)))) -> 1 | I26: - | J26: 已通过 | K26: 已上传 | N26: =IF($I26=N$8,"t","") | O26: =IF($I26=O$8,"t","") | P26: =IF($I26=P$8,"t","") | Q26: =IF($I26=Q$8,"t","") | R26: =IF($I26=R$8,"t","") | S26: =IF($I26=S$8,"t","") | T26: =IF($I26=T$8,"t","") | U26: =IF($I26=U$8,"t","") | ... DG26: =IF($I26=DG$8,"t","") -> #REF!
A27: =IF(ISERROR(VALUE(SUBSTITUTE(prevWBS,".",""))),"0.1",IF(ISERROR(FIND("`",SUBSTITUTE(prevWBS,".","`",1))),prevWBS&".1",LEFT(prevWBS,FIND("`",SUBSTITUTE(prevWBS,".","`",1)))&IF(ISERROR(FIND("`",SUBSTITUTE(prevWBS,".","`",2))),VALUE(RIGHT(prevWBS,LEN(prevWBS)-FIND("`",SUBSTITUTE(prevWBS,".","`",1))))+1,VALUE(MID(prevWBS,FIND("`",SUBSTITUTE(prevWBS,".","`",1))+1,(FIND("`",SUBSTITUTE(prevWBS,".","`",2))-FIND("`",SUBSTITUTE(prevWBS,".","`",1))-1)))+1))) -> 1.17 | B27: 202507014 | C27: =IF(C$7=-1,"",INDEX(INDEX('Project List'!$1:$1048576,0,C$7),MATCH($B27,'Project List'!$A:$A,0))) -> 四平路国泰路、四平路国定路燃气管道改造工程 | D27: =IF(D$7=-1,"",INDEX(INDEX('Project List'!$1:$1048576,0,D$7),MATCH($B27,'Project List'!$A:$A,0))) -> 管线 | E27: =IF(E$7=-1,"",INDEX(INDEX('Project List'!$1:$1048576,0,E$7),MATCH($B27,'Project List'!$A:$A,0))) -> 地铁运营线路10号线国权路站至五角场站区间 | F27: =IF(F$7=-1,"",INDEX(INDEX('Project List'!$1:$1048576,0,F$7),MATCH($B27,'Project List'!$A:$A,0))) -> 45973 | G27: =F27+7 -> 45980 | H27: =IF(OR(K27="销项",K27="已上传",K27="退回"),1,IF(K27="待上传",0.7,IF(K27="已发校审未返",0.3,IF(OR(K27="需沟通",K27="退回"),0,-1)))) -> 1 | I27: - | J27: 已通过 | K27: 已上传 | N27: =IF($I27=N$8,"t","") | O27: =IF($I27=O$8,"t","") | P27: =IF($I27=P$8,"t","") | Q27: =IF($I27=Q$8,"t","") | R27: =IF($I27=R$8,"t","") | S27: =IF($I27=S$8,"t","") | T27: =IF($I27=T$8,"t","") | U27: =IF($I27=U$8,"t","") | ... DG27: =IF($I27=DG$8,"t","") -> #REF!
A28: =IF(ISERROR(VALUE(SUBSTITUTE(prevWBS,".",""))),"0.1",IF(ISERROR(FIND("`",SUBSTITUTE(prevWBS,".","`",1))),prevWBS&".1",LEFT(prevWBS,FIND("`",SUBSTITUTE(prevWBS,".","`",1)))&IF(ISERROR(FIND("`",SUBSTITUTE(prevWBS,".","`",2))),VALUE(RIGHT(prevWBS,LEN(prevWBS)-FIND("`",SUBSTITUTE(prevWBS,".","`",1))))+1,VALUE(MID(prevWBS,FIND("`",SUBSTITUTE(prevWBS,".","`",1))+1,(FIND("`",SUBSTITUTE(prevWBS,".","`",2))-FIND("`",SUBSTITUTE(prevWBS,".","`",1))-1)))+1))) -> 1.18 | B28: 202510066 | C28: =IF(C$7=-1,"",INDEX(INDEX('Project List'!$1:$1048576,0,C$7),MATCH($B28,'Project List'!$A:$A,0))) -> 临平北路5弄、89弄、四平路288弄燃气管道改造 | D28: =IF(D$7=-1,"",INDEX(INDEX('Project List'!$1:$1048576,0,D$7),MATCH($B28,'Project List'!$A:$A,0))) -> 管线 | E28: =IF(E$7=-1,"",INDEX(INDEX('Project List'!$1:$1048576,0,E$7),MATCH($B28,'Project List'!$A:$A,0))) -> 地铁运营线路10号线四平路站至邮电新村站区间 | F28: =IF(F$7=-1,"",INDEX(INDEX('Project List'!$1:$1048576,0,F$7),MATCH($B28,'Project List'!$A:$A,0))) -> 45974 | G28: =F28+7 -> 45981 | H28: =IF(OR(K28="销项",K28="已上传",K28="退回"),1,IF(K28="待上传",0.7,IF(K28="已发校审未返",0.3,IF(OR(K28="需沟通",K28="退回"),0,-1)))) -> 1 | I28: - | J28: 已通过 | K28: 已上传 | N28: =IF($I28=N$8,"t","") | O28: =IF($I28=O$8,"t","") | P28: =IF($I28=P$8,"t","") | Q28: =IF($I28=Q$8,"t","") | R28: =IF($I28=R$8,"t","") | S28: =IF($I28=S$8,"t","") | T28: =IF($I28=T$8,"t","") | U28: =IF($I28=U$8,"t","") | ... DG28: =IF($I28=DG$8,"t","") -> #REF!
A29: =IF(ISERROR(VALUE(SUBSTITUTE(prevWBS,".",""))),"0.1",IF(ISERROR(FIND("`",SUBSTITUTE(prevWBS,".","`",1))),prevWBS&".1",LEFT(prevWBS,FIND("`",SUBSTITUTE(prevWBS,".","`",1)))&IF(ISERROR(FIND("`",SUBSTITUTE(prevWBS,".","`",2))),VALUE(RIGHT(prevWBS,LEN(prevWBS)-FIND("`",SUBSTITUTE(prevWBS,".","`",1))))+1,VALUE(MID(prevWBS,FIND("`",SUBSTITUTE(prevWBS,".","`",1))+1,(FIND("`",SUBSTITUTE(prevWBS,".","`",2))-FIND("`",SUBSTITUTE(prevWBS,".","`",1))-1)))+1))) -> 1.19 | B29: 202510073 | C29: =IF(C$7=-1,"",INDEX(INDEX('Project List'!$1:$1048576,0,C$7),MATCH($B29,'Project List'!$A:$A,0))) -> 四平路（庆阳路-溧阳路）燃气管道改造 | D29: =IF(D$7=-1,"",INDEX(INDEX('Project List'!$1:$1048576,0,D$7),MATCH($B29,'Project List'!$A:$A,0))) -> 管线 | E29: =IF(E$7=-1,"",INDEX(INDEX('Project List'!$1:$1048576,0,E$7),MATCH($B29,'Project List'!$A:$A,0))) -> 地铁运营线路10号线海伦路站至邮电新村站区间 | F29: =IF(F$7=-1,"",INDEX(INDEX('Project List'!$1:$1048576,0,F$7),MATCH($B29,'Project List'!$A:$A,0))) -> 45974 | G29: =F29+7 -> 45981 | H29: =IF(OR(K29="销项",K29="已上传",K29="退回"),1,IF(K29="待上传",0.7,IF(K29="已发校审未返",0.3,IF(OR(K29="需沟通",K29="退回"),0,-1)))) -> 1 | I29: - | J29: 退回 | K29: 退回 | L29: 本项目包含2段，其中1段涉及地铁运营线路10号线“四平路站~同济大学站”，该区间为双圆盾构，剖面需要修改；另一段涉及运营线路10号线“海伦路站（含）~邮电新村站”以及在建线路19号线“海伦路站（含）~甜爱路站”，距离在建19号线海伦路站4.3m，小于10m，属于非低风险项目。 | N29: =IF($I29=N$8,"t","") | O29: =IF($I29=O$8,"t","") | P29: =IF($I29=P$8,"t","") | Q29: =IF($I29=Q$8,"t","") | R29: =IF($I29=R$8,"t","") | S29: =IF($I29=S$8,"t","") | T29: =IF($I29=T$8,"t","") | U29: =IF($I29=U$8,"t","") | ... DG29: =IF($I29=DG$8,"t","") -> #REF!
A30: =IF(ISERROR(VALUE(SUBSTITUTE(prevWBS,".",""))),"0.1",IF(ISERROR(FIND("`",SUBSTITUTE(prevWBS,".","`",1))),prevWBS&".1",LEFT(prevWBS,FIND("`",SUBSTITUTE(prevWBS,".","`",1)))&IF(ISERROR(FIND("`",SUBSTITUTE(prevWBS,".","`",2))),VALUE(RIGHT(prevWBS,LEN(prevWBS)-FIND("`",SUBSTITUTE(prevWBS,".","`",1))))+1,VALUE(MID(prevWBS,FIND("`",SUBSTITUTE(prevWBS,".","`",1))+1,(FIND("`",SUBSTITUTE(prevWBS,".","`",2))-FIND("`",SUBSTITUTE(prevWBS,".","`",1))-1)))+1))) -> 1.20 | B30: 202510042 | C30: =IF(C$7=-1,"",INDEX(INDEX('Project List'!$1:$1048576,0,C$7),MATCH($B30,'Project List'!$A:$A,0))) -> 骏达路北段（曹安公路-童家桥路）燃气配套工程 | D30: =IF(D$7=-1,"",INDEX(INDEX('Project List'!$1:$1048576,0,D$7),MATCH($B30,'Project List'!$A:$A,0))) -> 管线 | E30: =IF(E$7=-1,"",INDEX(INDEX('Project List'!$1:$1048576,0,E$7),MATCH($B30,'Project List'!$A:$A,0))) -> 地铁运营线路14号线曹安公路站至嘉怡路站区间 | F30: =IF(F$7=-1,"",INDEX(INDEX('Project List'!$1:$1048576,0,F$7),MATCH($B30,'Project List'!$A:$A,0))) -> 45974 | G30: =F30+7 -> 45981 | H30: =IF(OR(K30="销项",K30="已上传",K30="退回"),1,IF(K30="待上传",0.7,IF(K30="已发校审未返",0.3,IF(OR(K30="需沟通",K30="退回"),0,-1)))) -> 1 | I30: - | J30: 已通过 | K30: 已上传 | N30: =IF($I30=N$8,"t","") | O30: =IF($I30=O$8,"t","") | P30: =IF($I30=P$8,"t","") | Q30: =IF($I30=Q$8,"t","") | R30: =IF($I30=R$8,"t","") | S30: =IF($I30=S$8,"t","") | T30: =IF($I30=T$8,"t","") | U30: =IF($I30=U$8,"t","") | ... DG30: =IF($I30=DG$8,"t","") -> #REF!
A31: =IF(ISERROR(VALUE(SUBSTITUTE(prevWBS,".",""))),"0.1",IF(ISERROR(FIND("`",SUBSTITUTE(prevWBS,".","`",1))),prevWBS&".1",LEFT(prevWBS,FIND("`",SUBSTITUTE(prevWBS,".","`",1)))&IF(ISERROR(FIND("`",SUBSTITUTE(prevWBS,".","`",2))),VALUE(RIGHT(prevWBS,LEN(prevWBS)-FIND("`",SUBSTITUTE(prevWBS,".","`",1))))+1,VALUE(MID(prevWBS,FIND("`",SUBSTITUTE(prevWBS,".","`",1))+1,(FIND("`",SUBSTITUTE(prevWBS,".","`",2))-FIND("`",SUBSTITUTE(prevWBS,".","`",1))-1)))+1))) -> 1.21 | B31: 202511035 | C31: =IF(C$7=-1,"",INDEX(INDEX('Project List'!$1:$1048576,0,C$7),MATCH($B31,'Project List'!$A:$A,0))) -> 圣安达公寓 | D31: =IF(D$7=-1,"",INDEX(INDEX('Project List'!$1:$1048576,0,D$7),MATCH($B31,'Project List'!$A:$A,0))) -> 勘探 | E31: =IF(E$7=-1,"",INDEX(INDEX('Project List'!$1:$1048576,0,E$7),MATCH($B31,'Project List'!$A:$A,0))) -> 地铁运营线路14号线铜川路站至真光路站区间 | F31: =IF(F$7=-1,"",INDEX(INDEX('Project List'!$1:$1048576,0,F$7),MATCH($B31,'Project List'!$A:$A,0))) -> 45975 | G31: =F31+7 -> 45982 | H31: =IF(OR(K31="销项",K31="已上传",K31="退回"),1,IF(K31="待上传",0.7,IF(K31="已发校审未返",0.3,IF(OR(K31="需沟通",K31="退回"),0,-1)))) -> 1 | I31: - | J31: 已通过 | K31: 已上传 | N31: =IF($I31=N$8,"t","") | O31: =IF($I31=O$8,"t","") | P31: =IF($I31=P$8,"t","") | Q31: =IF($I31=Q$8,"t","") | R31: =IF($I31=R$8,"t","") | S31: =IF($I31=S$8,"t","") | T31: =IF($I31=T$8,"t","") | U31: =IF($I31=U$8,"t","") | ... DG31: =IF($I31=DG$8,"t","") -> #REF!
A32: =IF(ISERROR(VALUE(SUBSTITUTE(prevWBS,".",""))),"0.1",IF(ISERROR(FIND("`",SUBSTITUTE(prevWBS,".","`",1))),prevWBS&".1",LEFT(prevWBS,FIND("`",SUBSTITUTE(prevWBS,".","`",1)))&IF(ISERROR(FIND("`",SUBSTITUTE(prevWBS,".","`",2))),VALUE(RIGHT(prevWBS,LEN(prevWBS)-FIND("`",SUBSTITUTE(prevWBS,".","`",1))))+1,VALUE(MID(prevWBS,FIND("`",SUBSTITUTE(prevWBS,".","`",1))+1,(FIND("`",SUBSTITUTE(prevWBS,".","`",2))-FIND("`",SUBSTITUTE(prevWBS,".","`",1))-1)))+1))) -> 1.22 | B32: 202507054 | C32: =IF(C$7=-1,"",INDEX(INDEX('Project List'!$1:$1048576,0,C$7),MATCH($B32,'Project List'!$A:$A,0))) -> 世博水环品质提升工程（一期）D段 | D32: =IF(D$7=-1,"",INDEX(INDEX('Project List'!$1:$1048576,0,D$7),MATCH($B32,'Project List'!$A:$A,0))) -> 绿化 | E32: =IF(E$7=-1,"",INDEX(INDEX('Project List'!$1:$1048576,0,E$7),MATCH($B32,'Project List'!$A:$A,0))) -> 地铁运营线路11号线三林站至三林东站区间 | F32: =IF(F$7=-1,"",INDEX(INDEX('Project List'!$1:$1048576,0,F$7),MATCH($B32,'Project List'!$A:$A,0))) -> 45975 | G32: =F32+7 -> 45982 | H32: =IF(OR(K32="销项",K32="已上传",K32="退回"),1,IF(K32="待上传",0.7,IF(K32="已发校审未返",0.3,IF(OR(K32="需沟通",K32="退回"),0,-1)))) -> 1 | I32: - | J32: 退回 | K32: 退回 | L32: 报审资料位置与标图位置不一致。 | N32: =IF($I32=N$8,"t","") | O32: =IF($I32=O$8,"t","") | P32: =IF($I32=P$8,"t","") | Q32: =IF($I32=Q$8,"t","") | R32: =IF($I32=R$8,"t","") | S32: =IF($I32=S$8,"t","") | T32: =IF($I32=T$8,"t","") | U32: =IF($I32=U$8,"t","") | ... DG32: =IF($I32=DG$8,"t","") -> #REF!
A33: =IF(ISERROR(VALUE(SUBSTITUTE(prevWBS,".",""))),"0.1",IF(ISERROR(FIND("`",SUBSTITUTE(prevWBS,".","`",1))),prevWBS&".1",LEFT(prevWBS,FIND("`",SUBSTITUTE(prevWBS,".","`",1)))&IF(ISERROR(FIND("`",SUBSTITUTE(prevWBS,".","`",2))),VALUE(RIGHT(prevWBS,LEN(prevWBS)-FIND("`",SUBSTITUTE(prevWBS,".","`",1))))+1,VALUE(MID(prevWBS,FIND("`",SUBSTITUTE(prevWBS,".","`",1))+1,(FIND("`",SUBSTITUTE(prevWBS,".","`",2))-FIND("`",SUBSTITUTE(prevWBS,".","`",1))-1)))+1))) -> 1.23 | B33: 202510065 | C33: =IF(C$7=-1,"",INDEX(INDEX('Project List'!$1:$1048576,0,C$7),MATCH($B33,'Project List'!$A:$A,0))) -> 广纪路65弄燃气管道改造 | D33: =IF(D$7=-1,"",INDEX(INDEX('Project List'!$1:$1048576,0,D$7),MATCH($B33,'Project List'!$A:$A,0))) -> 管线 | E33: =IF(E$7=-1,"",INDEX(INDEX('Project List'!$1:$1048576,0,E$7),MATCH($B33,'Project List'!$A:$A,0))) -> 地铁运营线路3号线赤峰路车站 | F33: =IF(F$7=-1,"",INDEX(INDEX('Project List'!$1:$1048576,0,F$7),MATCH($B33,'Project List'!$A:$A,0))) -> 45979 | G33: =F33+7 -> 45986 | H33: =IF(OR(K33="销项",K33="已上传",K33="退回"),1,IF(K33="待上传",0.7,IF(K33="已发校审未返",0.3,IF(OR(K33="需沟通",K33="退回"),0,-1)))) -> 1 | I33: - | J33: 已通过 | K33: 已上传 | N33: =IF($I33=N$8,"t","") | O33: =IF($I33=O$8,"t","") | P33: =IF($I33=P$8,"t","") | Q33: =IF($I33=Q$8,"t","") | R33: =IF($I33=R$8,"t","") | S33: =IF($I33=S$8,"t","") | T33: =IF($I33=T$8,"t","") | U33: =IF($I33=U$8,"t","") | ... DG33: =IF($I33=DG$8,"t","") -> #REF!
A34: =IF(ISERROR(VALUE(SUBSTITUTE(prevWBS,".",""))),"0.1",IF(ISERROR(FIND("`",SUBSTITUTE(prevWBS,".","`",1))),prevWBS&".1",LEFT(prevWBS,FIND("`",SUBSTITUTE(prevWBS,".","`",1)))&IF(ISERROR(FIND("`",SUBSTITUTE(prevWBS,".","`",2))),VALUE(RIGHT(prevWBS,LEN(prevWBS)-FIND("`",SUBSTITUTE(prevWBS,".","`",1))))+1,VALUE(MID(prevWBS,FIND("`",SUBSTITUTE(prevWBS,".","`",1))+1,(FIND("`",SUBSTITUTE(prevWBS,".","`",2))-FIND("`",SUBSTITUTE(prevWBS,".","`",1))-1)))+1))) -> 1.24 | B34: 202510064 | C34: =IF(C$7=-1,"",INDEX(INDEX('Project List'!$1:$1048576,0,C$7),MATCH($B34,'Project List'!$A:$A,0))) -> 广纪路19号燃气管道改造 | D34: =IF(D$7=-1,"",INDEX(INDEX('Project List'!$1:$1048576,0,D$7),MATCH($B34,'Project List'!$A:$A,0))) -> 管线 | E34: =IF(E$7=-1,"",INDEX(INDEX('Project List'!$1:$1048576,0,E$7),MATCH($B34,'Project List'!$A:$A,0))) -> 地铁运营线路3号线虹口足球场站至赤峰路站区间 | F34: =IF(F$7=-1,"",INDEX(INDEX('Project List'!$1:$1048576,0,F$7),MATCH($B34,'Project List'!$A:$A,0))) -> 45979 | G34: =F34+7 -> 45986 | H34: =IF(OR(K34="销项",K34="已上传",K34="退回"),1,IF(K34="待上传",0.7,IF(K34="已发校审未返",0.3,IF(OR(K34="需沟通",K34="退回"),0,-1)))) -> 1 | I34: - | J34: 已通过 | K34: 已上传 | N34: =IF($I34=N$8,"t","") | O34: =IF($I34=O$8,"t","") | P34: =IF($I34=P$8,"t","") | Q34: =IF($I34=Q$8,"t","") | R34: =IF($I34=R$8,"t","") | S34: =IF($I34=S$8,"t","") | T34: =IF($I34=T$8,"t","") | U34: =IF($I34=U$8,"t","") | ... DG34: =IF($I34=DG$8,"t","") -> #REF!
A35: =IF(ISERROR(VALUE(SUBSTITUTE(prevWBS,".",""))),"0.1",IF(ISERROR(FIND("`",SUBSTITUTE(prevWBS,".","`",1))),prevWBS&".1",LEFT(prevWBS,FIND("`",SUBSTITUTE(prevWBS,".","`",1)))&IF(ISERROR(FIND("`",SUBSTITUTE(prevWBS,".","`",2))),VALUE(RIGHT(prevWBS,LEN(prevWBS)-FIND("`",SUBSTITUTE(prevWBS,".","`",1))))+1,VALUE(MID(prevWBS,FIND("`",SUBSTITUTE(prevWBS,".","`",1))+1,(FIND("`",SUBSTITUTE(prevWBS,".","`",2))-FIND("`",SUBSTITUTE(prevWBS,".","`",1))-1)))+1))) -> 1.25 | B35: 202510099 | C35: =IF(C$7=-1,"",INDEX(INDEX('Project List'!$1:$1048576,0,C$7),MATCH($B35,'Project List'!$A:$A,0))) -> 广纪路171弄、中山北一路665号燃气管道改造 | D35: =IF(D$7=-1,"",INDEX(INDEX('Project List'!$1:$1048576,0,D$7),MATCH($B35,'Project List'!$A:$A,0))) -> 管线 | E35: =IF(E$7=-1,"",INDEX(INDEX('Project List'!$1:$1048576,0,E$7),MATCH($B35,'Project List'!$A:$A,0))) -> 地铁运营线路3号线大柏树站至赤峰路站区间 | F35: =IF(F$7=-1,"",INDEX(INDEX('Project List'!$1:$1048576,0,F$7),MATCH($B35,'Project List'!$A:$A,0))) -> 45979 | G35: =F35+7 -> 45986 | H35: =IF(OR(K35="销项",K35="已上传",K35="退回"),1,IF(K35="待上传",0.7,IF(K35="已发校审未返",0.3,IF(OR(K35="需沟通",K35="退回"),0,-1)))) -> 1 | I35: - | J35: 已通过 | K35: 已上传 | N35: =IF($I35=N$8,"t","") | O35: =IF($I35=O$8,"t","") | P35: =IF($I35=P$8,"t","") | Q35: =IF($I35=Q$8,"t","") | R35: =IF($I35=R$8,"t","") | S35: =IF($I35=S$8,"t","") | T35: =IF($I35=T$8,"t","") | U35: =IF($I35=U$8,"t","") | ... DG35: =IF($I35=DG$8,"t","") -> #REF!
A36: =IF(ISERROR(VALUE(SUBSTITUTE(prevWBS,".",""))),"0.1",IF(ISERROR(FIND("`",SUBSTITUTE(prevWBS,".","`",1))),prevWBS&".1",LEFT(prevWBS,FIND("`",SUBSTITUTE(prevWBS,".","`",1)))&IF(ISERROR(FIND("`",SUBSTITUTE(prevWBS,".","`",2))),VALUE(RIGHT(prevWBS,LEN(prevWBS)-FIND("`",SUBSTITUTE(prevWBS,".","`",1))))+1,VALUE(MID(prevWBS,FIND("`",SUBSTITUTE(prevWBS,".","`",1))+1,(FIND("`",SUBSTITUTE(prevWBS,".","`",2))-FIND("`",SUBSTITUTE(prevWBS,".","`",1))-1)))+1))) -> 1.26 | B36: 202511063 | C36: =IF(C$7=-1,"",INDEX(INDEX('Project List'!$1:$1048576,0,C$7),MATCH($B36,'Project List'!$A:$A,0))) -> 皋兰山路武威路上水排管项目 | D36: =IF(D$7=-1,"",INDEX(INDEX('Project List'!$1:$1048576,0,D$7),MATCH($B36,'Project List'!$A:$A,0))) -> 管线 | E36: =IF(E$7=-1,"",INDEX(INDEX('Project List'!$1:$1048576,0,E$7),MATCH($B36,'Project List'!$A:$A,0))) -> 地铁运营线路11号线武威路车站或桃浦新村站至武威路站区间 | F36: =IF(F$7=-1,"",INDEX(INDEX('Project List'!$1:$1048576,0,F$7),MATCH($B36,'Project List'!$A:$A,0))) -> 45980 | G36: =F36+7 -> 45987 | H36: =IF(OR(K36="销项",K36="已上传",K36="退回"),1,IF(K36="待上传",0.7,IF(K36="已发校审未返",0.3,IF(OR(K36="需沟通",K36="退回"),0,-1)))) -> 1 | I36: - | J36: 已通过 | K36: 退回 | N36: =IF($I36=N$8,"t","") | O36: =IF($I36=O$8,"t","") | P36: =IF($I36=P$8,"t","") | Q36: =IF($I36=Q$8,"t","") | R36: =IF($I36=R$8,"t","") | S36: =IF($I36=S$8,"t","") | T36: =IF($I36=T$8,"t","") | U36: =IF($I36=U$8,"t","") | ... DG36: =IF($I36=DG$8,"t","") -> #REF!
A37: =IF(ISERROR(VALUE(SUBSTITUTE(prevWBS,".",""))),"0.1",IF(ISERROR(FIND("`",SUBSTITUTE(prevWBS,".","`",1))),prevWBS&".1",LEFT(prevWBS,FIND("`",SUBSTITUTE(prevWBS,".","`",1)))&IF(ISERROR(FIND("`",SUBSTITUTE(prevWBS,".","`",2))),VALUE(RIGHT(prevWBS,LEN(prevWBS)-FIND("`",SUBSTITUTE(prevWBS,".","`",1))))+1,VALUE(MID(prevWBS,FIND("`",SUBSTITUTE(prevWBS,".","`",1))+1,(FIND("`",SUBSTITUTE(prevWBS,".","`",2))-FIND("`",SUBSTITUTE(prevWBS,".","`",1))-1)))+1))) -> 1.27 | B37: 202504072 | C37: =IF(C$7=-1,"",INDEX(INDEX('Project List'!$1:$1048576,0,C$7),MATCH($B37,'Project List'!$A:$A,0))) -> 世博水环品质提升工程（一期）D段 | D37: =IF(D$7=-1,"",INDEX(INDEX('Project List'!$1:$1048576,0,D$7),MATCH($B37,'Project List'!$A:$A,0))) -> 绿化 | E37: =IF(E$7=-1,"",INDEX(INDEX('Project List'!$1:$1048576,0,E$7),MATCH($B37,'Project List'!$A:$A,0))) -> 地铁运营线路11号线三林站至三林东站区间 | F37: =IF(F$7=-1,"",INDEX(INDEX('Project List'!$1:$1048576,0,F$7),MATCH($B37,'Project List'!$A:$A,0))) -> 45981 | G37: =F37+7 -> 45988 | H37: =IF(OR(K37="销项",K37="已上传",K37="退回"),1,IF(K37="待上传",0.7,IF(K37="已发校审未返",0.3,IF(OR(K37="需沟通",K37="退回"),0,-1)))) -> 0.3 | I37: - | J37: 已通过 | K37: 已发校审未返 | N37: =IF($I37=N$8,"t","") | O37: =IF($I37=O$8,"t","") | P37: =IF($I37=P$8,"t","") | Q37: =IF($I37=Q$8,"t","") | R37: =IF($I37=R$8,"t","") | S37: =IF($I37=S$8,"t","") | T37: =IF($I37=T$8,"t","") | U37: =IF($I37=U$8,"t","") | ... DG37: =IF($I37=DG$8,"t","") -> #REF!
A38: =IF(ISERROR(VALUE(SUBSTITUTE(prevWBS,".",""))),"0.1",IF(ISERROR(FIND("`",SUBSTITUTE(prevWBS,".","`",1))),prevWBS&".1",LEFT(prevWBS,FIND("`",SUBSTITUTE(prevWBS,".","`",1)))&IF(ISERROR(FIND("`",SUBSTITUTE(prevWBS,".","`",2))),VALUE(RIGHT(prevWBS,LEN(prevWBS)-FIND("`",SUBSTITUTE(prevWBS,".","`",1))))+1,VALUE(MID(prevWBS,FIND("`",SUBSTITUTE(prevWBS,".","`",1))+1,(FIND("`",SUBSTITUTE(prevWBS,".","`",2))-FIND("`",SUBSTITUTE(prevWBS,".","`",1))-1)))+1))) -> 1.28 | B38: 202511064 | C38: =IF(C$7=-1,"",INDEX(INDEX('Project List'!$1:$1048576,0,C$7),MATCH($B38,'Project List'!$A:$A,0))) -> 上海市区长宁愚园路699号项目接入工程 | D38: =IF(D$7=-1,"",INDEX(INDEX('Project List'!$1:$1048576,0,D$7),MATCH($B38,'Project List'!$A:$A,0))) -> 管线 | E38: =IF(E$7=-1,"",INDEX(INDEX('Project List'!$1:$1048576,0,E$7),MATCH($B38,'Project List'!$A:$A,0))) -> 地铁运营线路2号线静安寺车站或江苏路站至江苏路站区间 | F38: =IF(F$7=-1,"",INDEX(INDEX('Project List'!$1:$1048576,0,F$7),MATCH($B38,'Project List'!$A:$A,0))) -> 45981 | G38: =F38+7 -> 45988 | H38: =IF(OR(K38="销项",K38="已上传",K38="退回"),1,IF(K38="待上传",0.7,IF(K38="已发校审未返",0.3,IF(OR(K38="需沟通",K38="退回"),0,-1)))) -> 1 | I38: - | J38: 已通过 | K38: 已上传 | N38: =IF($I38=N$8,"t","") | O38: =IF($I38=O$8,"t","") | P38: =IF($I38=P$8,"t","") | Q38: =IF($I38=Q$8,"t","") | R38: =IF($I38=R$8,"t","") | S38: =IF($I38=S$8,"t","") | T38: =IF($I38=T$8,"t","") | U38: =IF($I38=U$8,"t","") | ... DG38: =IF($I38=DG$8,"t","") -> #REF!
A39: =IF(ISERROR(VALUE(SUBSTITUTE(prevWBS,".",""))),"0.1",IF(ISERROR(FIND("`",SUBSTITUTE(prevWBS,".","`",1))),prevWBS&".1",LEFT(prevWBS,FIND("`",SUBSTITUTE(prevWBS,".","`",1)))&IF(ISERROR(FIND("`",SUBSTITUTE(prevWBS,".","`",2))),VALUE(RIGHT(prevWBS,LEN(prevWBS)-FIND("`",SUBSTITUTE(prevWBS,".","`",1))))+1,VALUE(MID(prevWBS,FIND("`",SUBSTITUTE(prevWBS,".","`",1))+1,(FIND("`",SUBSTITUTE(prevWBS,".","`",2))-FIND("`",SUBSTITUTE(prevWBS,".","`",1))-1)))+1))) -> 1.29 | B39: 202503068 | C39: =IF(C$7=-1,"",INDEX(INDEX('Project List'!$1:$1048576,0,C$7),MATCH($B39,'Project List'!$A:$A,0))) -> 浦东新区张杨路城市资源回收中心项目 | D39: =IF(D$7=-1,"",INDEX(INDEX('Project List'!$1:$1048576,0,D$7),MATCH($B39,'Project List'!$A:$A,0))) -> 0 | E39: =IF(E$7=-1,"",INDEX(INDEX('Project List'!$1:$1048576,0,E$7),MATCH($B39,'Project List'!$A:$A,0))) -> 0 | F39: =IF(F$7=-1,"",INDEX(INDEX('Project List'!$1:$1048576,0,F$7),MATCH($B39,'Project List'!$A:$A,0))) -> 0 | G39: =F39+7 -> 7 | H39: =IF(OR(K39="销项",K39="已上传",K39="退回"),1,IF(K39="待上传",0.7,IF(K39="已发校审未返",0.3,IF(OR(K39="需沟通",K39="退回"),0,-1)))) -> 0.3 | I39: - | J39: 已通过 | K39: 已发校审未返 | N39: =IF($I39=N$8,"t","") | O39: =IF($I39=O$8,"t","") | P39: =IF($I39=P$8,"t","") | Q39: =IF($I39=Q$8,"t","") | R39: =IF($I39=R$8,"t","") | S39: =IF($I39=S$8,"t","") | T39: =IF($I39=T$8,"t","") | U39: =IF($I39=U$8,"t","") | ... DG39: =IF($I39=DG$8,"t","") -> #REF!
A40: =IF(ISERROR(VALUE(SUBSTITUTE(prevWBS,".",""))),"0.1",IF(ISERROR(FIND("`",SUBSTITUTE(prevWBS,".","`",1))),prevWBS&".1",LEFT(prevWBS,FIND("`",SUBSTITUTE(prevWBS,".","`",1)))&IF(ISERROR(FIND("`",SUBSTITUTE(prevWBS,".","`",2))),VALUE(RIGHT(prevWBS,LEN(prevWBS)-FIND("`",SUBSTITUTE(prevWBS,".","`",1))))+1,VALUE(MID(prevWBS,FIND("`",SUBSTITUTE(prevWBS,".","`",1))+1,(FIND("`",SUBSTITUTE(prevWBS,".","`",2))-FIND("`",SUBSTITUTE(prevWBS,".","`",1))-1)))+1))) -> 1.30 | B40: 202511028 | C40: =IF(C$7=-1,"",INDEX(INDEX('Project List'!$1:$1048576,0,C$7),MATCH($B40,'Project List'!$A:$A,0))) -> 申江路(陇桥路-新金桥路)信息管道工程项目 | D40: =IF(D$7=-1,"",INDEX(INDEX('Project List'!$1:$1048576,0,D$7),MATCH($B40,'Project List'!$A:$A,0))) -> 管线 | E40: =IF(E$7=-1,"",INDEX(INDEX('Project List'!$1:$1048576,0,E$7),MATCH($B40,'Project List'!$A:$A,0))) -> 地铁运营线路9号线金桥站至金吉路站区间 | F40: =IF(F$7=-1,"",INDEX(INDEX('Project List'!$1:$1048576,0,F$7),MATCH($B40,'Project List'!$A:$A,0))) -> 45985 | G40: =F40+7 -> 45992 | H40: =IF(OR(K40="销项",K40="已上传",K40="退回"),1,IF(K40="待上传",0.7,IF(K40="已发校审未返",0.3,IF(OR(K40="需沟通",K40="退回"),0,-1)))) -> -1 | I40: - | J40: 已通过 | N40: =IF($I40=N$8,"t","") | O40: =IF($I40=O$8,"t","") | P40: =IF($I40=P$8,"t","") | Q40: =IF($I40=Q$8,"t","") | R40: =IF($I40=R$8,"t","") | S40: =IF($I40=S$8,"t","") | T40: =IF($I40=T$8,"t","") | U40: =IF($I40=U$8,"t","") | ... DG40: =IF($I40=DG$8,"t","") -> #REF!
A41: =IF(ISERROR(VALUE(SUBSTITUTE(prevWBS,".",""))),"0.1",IF(ISERROR(FIND("`",SUBSTITUTE(prevWBS,".","`",1))),prevWBS&".1",LEFT(prevWBS,FIND("`",SUBSTITUTE(prevWBS,".","`",1)))&IF(ISERROR(FIND("`",SUBSTITUTE(prevWBS,".","`",2))),VALUE(RIGHT(prevWBS,LEN(prevWBS)-FIND("`",SUBSTITUTE(prevWBS,".","`",1))))+1,VALUE(MID(prevWBS,FIND("`",SUBSTITUTE(prevWBS,".","`",1))+1,(FIND("`",SUBSTITUTE(prevWBS,".","`",2))-FIND("`",SUBSTITUTE(prevWBS,".","`",1))-1)))+1))) -> 1.31 | B41: 20251102901 | C41: =IF(C$7=-1,"",INDEX(INDEX('Project List'!$1:$1048576,0,C$7),MATCH($B41,'Project List'!$A:$A,0))) -> 申江路(新金桥路-电台路)信息管道工程项目 | D41: =IF(D$7=-1,"",INDEX(INDEX('Project List'!$1:$1048576,0,D$7),MATCH($B41,'Project List'!$A:$A,0))) -> 管线 | E41: =IF(E$7=-1,"",INDEX(INDEX('Project List'!$1:$1048576,0,E$7),MATCH($B41,'Project List'!$A:$A,0))) -> 地铁运营线路14号线浦东足球场站站至金粤路站区间 | F41: =IF(F$7=-1,"",INDEX(INDEX('Project List'!$1:$1048576,0,F$7),MATCH($B41,'Project List'!$A:$A,0))) -> 45985 | G41: =F41+7 -> 45992 | H41: =IF(OR(K41="销项",K41="已上传",K41="退回"),1,IF(K41="待上传",0.7,IF(K41="已发校审未返",0.3,IF(OR(K41="需沟通",K41="退回"),0,-1)))) -> -1 | I41: - | J41: 已通过 | N41: =IF($I41=N$8,"t","") | O41: =IF($I41=O$8,"t","") | P41: =IF($I41=P$8,"t","") | Q41: =IF($I41=Q$8,"t","") | R41: =IF($I41=R$8,"t","") | S41: =IF($I41=S$8,"t","") | T41: =IF($I41=T$8,"t","") | U41: =IF($I41=U$8,"t","") | ... DG41: =IF($I41=DG$8,"t","") -> #REF!
...

Sheet Notes & Inputs
B2: Col E-F: Enter start and end date of a task. The gantt chart will update accordingly
B3: Col G: If task has a milestone date or meeting date, enter here and a diamond will appear
B4: Col H: input a % to indicate % completion fro the task. The Gant chart will update
B5: Cell G6 (Display Week): The gantt chart only displays 12 weeks. You can either add columns to extend it (becareful of conditional formatting issues if you copy - ask Wen). Or enter a different display week in G6
B6: Row 4 Arrow bar: to move further on the timeline you can also CLICK AND STAY (NOT Click and Hold) on either the left or right arrow to move the gantt chart forward or backward
B7: 2018 and 2019 holidays have been included. Make sure you update if you're using this in 2020
B8: TO ADD TASKS: copy an EXISTING row and insert copied row. DO NOT INSERT AN EMPTY ROW. Choose the appropriate task level (e.g., 1.1 vs 1.1.1 vs 1.1.1 depending on how deep the subtasks are)
B9: COL A (Step): updates automatically
B10: The grey rows in columns E & F updates automatically. If you add additional grey rows make sure you copy the formulas along
B11: There are formulas in column K onwards. DO NOT DELETE
B12: ROWS 40-43: Keep them unused so that you can use them to copy formulas
B16: INPUTS
B18: Enter project start date here | C18: 45962
B21: Roles
B42: 2022-23
B43: The first day of January | C43: 44928 | D43: Friday
B45: The first day of January | C45: 44928 | D45: Saturday

Sheet 低风险项目
A1: =MATCH(A$2,'Project List'!$2:$2,0) -> 1 | B1: =_xlfn.IFNA(MATCH(B$2,'Project List'!$2:$2,0),-1) -> 2 | C1: =_xlfn.IFNA(MATCH(C$2,'Project List'!$2:$2,0),-1) -> 20 | D1: =_xlfn.IFNA(MATCH(D$2,'Project List'!$2:$2,0),-1) -> 11 | E1: =_xlfn.IFNA(MATCH(E$2,'Project List'!$2:$2,0),-1) -> 8 | F1: =_xlfn.IFNA(MATCH(F$2,'Project List'!$2:$2,0),-1) -> 11 | G1: =_xlfn.IFNA(MATCH(G$2,'Project List'!$2:$2,0),-1) -> 12 | H1: =_xlfn.IFNA(MATCH(H$2,'Project List'!$2:$2,0),-1) -> 13 | I1: =_xlfn.IFNA(MATCH(I$2,'Project List'!$2:$2,0),-1) -> -1 | ... V1: =_xlfn.IFNA(MATCH(V$2,'Project List'!$2:$2,0),-1) -> -1
A2: 项目编号 | B2: 项目名称 | C2: 项目类型 | D2: 建设单位 | E2: 申报类型 | F2: 建设单位 | G2: 项目地理位置 | H2: 与轨道交通关系 | I2: 车站信息补充 | J2: 是否涉及规划 | K2: 是否涉及在建线路 | L2: 是否涉及申铁线路 | M2: 地区 | N2: 项目位置 | O2: 线路 | P2: 车站 | Q2: 区间 | R2: 其他设施 | S2: 申报工期 | T2: 是否为低风险 | U2: 低风险类型 | V2: 生成文件 | W2: 监护大 纲状态 | X2: 技审状态
